#VRML_SIM R2022a utf8
WorldInfo {
}
Viewpoint {
  fieldOfView 1.1
  orientation -0.5286929152477025 -0.1024730433324457 0.8426049351606436 3.501734867240019
  position 0.3980181076485858 -1.3334804432683574 1.7100522724545546
  exposure 0.7999999999999999
}
TexturedBackground {
  texture "empty_office"
  skybox FALSE
  skyColor [
    0.2 0.2 0.2
  ]
}
Wall {
  translation -2.25 1.35 0
  name "wall(4)"
}
Wall {
  translation -2.25 -0.45 0
  name "wall(5)"
}
Wall {
  translation -2.25 -2.985 0
  name "wall(6)"
  size 0.2 2.07 2.4
}
Wall {
  translation -0.5 -3.92 0
  name "wall(7)"
  size 3.3 0.2 2.4
}
Door {
  hidden translation_5 0.0010000002705243816 8.485923075340907e-11 0
  hidden rotation_5 0 0 1 0
  translation -2.25 -1.45 0
  position -6.2160437748783394e-09
}
SolidBox {
  translation -2.146 0.455 0.03
  rotation 0 0 1 1.5708
  name "box(6)"
  size 2.8 0.01 0.07
  appearance PBRAppearance {
    baseColor 0.8 0.8 0.8
    roughness 0.5
    metalness 0
    textureTransform TextureTransform {
      scale 1 8
    }
  }
}
SolidBox {
  translation -2.145 -2.885 0.03
  rotation 0 0 1 1.5708
  name "box(7)"
  size 1.87 0.01 0.07
  appearance PBRAppearance {
    baseColor 0.8 0.8 0.8
    roughness 0.5
    metalness 0
    textureTransform TextureTransform {
      scale 1 8
    }
  }
}
SolidBox {
  translation -0.495 -3.815 0.03
  rotation 0 0 1 3.14159
  size 3.29 0.01 0.07
  appearance PBRAppearance {
    baseColor 0.8 0.8 0.8
    roughness 0.5
    metalness 0
    textureTransform TextureTransform {
      scale 1 8
    }
  }
}
Window {
  translation -2.25 0.45 0
  rotation 0 0 1 3.14159
  name "window(1)"
  bottomWallHeight 0.9
  windowHeight 1
  windowSillSize 0.01 0.05
}
CeilingLight {
  translation -0.93 -1.04 2.4
  pointLightColor 1 0.9764705882352941 0.9058823529411765
  pointLightIntensity 4
}
Floor {
  translation 0.8 -0.8 0.01
  name "floor(1)"
  size 0.04 4
  tileSize 1 1
  appearance Parquetry {
    type "chequered"
    colorOverride 0 0 0
  }
}
Floor {
  translation -1.35 0 0.01
  rotation 0 0 1 1.57079633
  name "floor(5)"
  size 0.04 0.7
  tileSize 1 1
  appearance Parquetry {
    type "chequered"
    colorOverride 0 0 0
  }
}
Floor {
  translation -0.66 -2.078 0.01
  rotation 0 0 1 1.57079633
  name "floor(7)"
  size 0.04 0.7
  tileSize 1 1
  appearance Parquetry {
    type "chequered"
    colorOverride 0 0 0
  }
}
Floor {
  translation 0.45 -1.5 0.01
  rotation 0 0 1 1.57079633
  name "floor(9)"
  size 0.04 0.7
  tileSize 1 1
  appearance Parquetry {
    type "chequered"
    colorOverride 0 0 0
  }
}
Floor {
  translation -0.3 0.81 0.01
  name "floor(11)"
  size 0.04 0.7
  tileSize 1 1
  appearance Parquetry {
    type "chequered"
    colorOverride 0 0 0
  }
}
Floor {
  translation 0.03 0.45 0.01
  rotation 0 0 1 1.57079633
  name "floor(10)"
  size 0.04 0.7
  tileSize 0.5 1
  appearance Parquetry {
    type "chequered"
    colorOverride 0 0 0
  }
}
Floor {
  translation -1.025 -1.05 0.01
  name "floor(8)"
  size 0.04 2.1
  tileSize 1 1
  appearance Parquetry {
    type "chequered"
    colorOverride 0 0 0
  }
}
Floor {
  translation -0.4 -0.6 0.01
  name "floor(12)"
  size 0.04 1
  tileSize 1 1
  appearance Parquetry {
    type "chequered"
    colorOverride 0 0 0
  }
}
Floor {
  translation -0.1 -0.6 0.01
  rotation 0 0 1 1.5707996938995747
  name "floor(13)"
  size 0.04 0.6
  tileSize 1 1
  appearance Parquetry {
    type "chequered"
    colorOverride 0 0 0
  }
}
Floor {
  translation -0.45 1.175 0.01
  rotation 0 0 1 1.57079633
  name "floor(3)"
  size 0.04 2.5
  tileSize 1 1
  appearance Parquetry {
    type "chequered"
    colorOverride 0 0 0
  }
}
Robot {
  translation -0.47417757406559674 -1.751376947320365 0.04000635406955949
  rotation -0.0006637142462494745 -0.00011695161199687929 0.999999772902834 0.2259039859928694
  children [
    LightSensor {
      translation 0.007 -0.07 0.013
      rotation 0 0 1 -1.5707953071795862
      children [
        Solid {
          children [
            Shape {
              appearance PBRAppearance {
                baseColor 1 1 0
              }
              geometry Box {
                size 0.002 0.01 0.01
              }
            }
          ]
        }
      ]
    }
    GPS {
      children [
        Solid {
          translation 0 0 0.01
          children [
            Shape {
              appearance PBRAppearance {
              }
              geometry Cylinder {
                height 0.01
                radius 0.0025
              }
            }
          ]
        }
      ]
      name "middleGPS"
    }
    GPS {
      translation 0 -0.07 0
      children [
        Solid {
          translation 0 0 0.01
          rotation 0 0 1 3.14159
          children [
            Shape {
              appearance PBRAppearance {
              }
              geometry Cylinder {
                height 0.01
                radius 0.0025
              }
            }
          ]
        }
      ]
      name "frontGPS"
    }
    Solid {
      translation 0 0 0.003
      children [
        Shape {
          appearance PBRAppearance {
          }
          geometry Box {
            size 0.08 0.15 0.003125
          }
        }
      ]
      name "solid(2)"
    }
    Solid {
      translation 0 0 0.006
      rotation 0 1 0 0
      children [
        Shape {
          appearance PBRAppearance {
            baseColor 0.666667 0 1
          }
          geometry Box {
            size 0.08 0.15 0.003125
          }
        }
      ]
      name "solid(3)"
    }
    BallJoint {
      jointParameters BallJointParameters {
        position -2.0655154222569414
        anchor 0 0.06 -0.02
      }
      jointParameters2 JointParameters {
        position -21.14903346362728
      }
      jointParameters3 JointParameters {
        position 5.66252467950093
        axis 0 1 0
      }
      endPoint Solid {
        translation 0 0.06 -0.02
        rotation -0.6148831533312771 0.7593113885435431 -0.21299042930953896 2.2331280570475
        children [
          DEF caster Shape {
            appearance PBRAppearance {
            }
            geometry Sphere {
              radius 0.01
            }
          }
        ]
        boundingObject USE caster
        physics Physics {
        }
      }
    }
    Solid {
      translation 0 0.06 -0.01
      children [
        Shape {
          appearance PBRAppearance {
            baseColor 0 0 0
          }
          geometry Cylinder {
            height 0.017
            radius 0.011
          }
        }
      ]
      name "solid(1)"
    }
    HingeJoint {
      jointParameters HingeJointParameters {
        position 2.740210974820109e-08
        anchor 0 -0.04 0
      }
      device [
        DEF wheel_left RotationalMotor {
          name "wheel_left"
          maxVelocity 30
        }
      ]
      endPoint DEF wheel_left Solid {
        translation 0.04296759999999994 -0.03998419999974723 -1.4646688262021372e-05
        rotation 0.5775878509908918 0.5773364172172278 -0.5771264469269264 4.189461511676189
        children [
          DEF wheel_left Shape {
            appearance PBRAppearance {
              baseColor 0.145098 0.145098 0.145098
              metalness 0
            }
            geometry Cylinder {
              height 0.005
              radius 0.03
            }
          }
        ]
        name "wheel_left"
        boundingObject USE wheel_left
        physics DEF Physics_wh Physics {
        }
      }
    }
    HingeJoint {
      jointParameters HingeJointParameters {
        position 0.008791816832634277
        anchor 0 -0.04 0
      }
      device [
        DEF wheel_right RotationalMotor {
          name "wheel_right"
          maxVelocity 30
        }
      ]
      endPoint DEF wheel_right Solid {
        translation -0.042031599999999975 -0.039920075042362904 -1.386176943598116e-05
        rotation 0.5758883126444175 0.5807193570791794 -0.5754282576247972 4.194530556268155
        children [
          DEF wheel_right Shape {
            appearance PBRAppearance {
              baseColor 0.145098 0.145098 0.145098
              metalness 0
            }
            geometry Cylinder {
              height 0.005
              radius 0.03
            }
          }
        ]
        name "wheel_right"
        boundingObject USE wheel_right
        physics DEF Physics_wh Physics {
        }
      }
    }
    DEF Body1 Shape {
      appearance PBRAppearance {
        baseColor 1 0.666667 1
      }
      geometry Box {
        size 0.08 0.15 0.003125
      }
    }
  ]
  boundingObject USE Body1
  physics Physics {
  }
  controller "pyController"
}
Robot {
  translation -0.255458 -2.26812 0.040112
  rotation -0.0006637142462494745 -0.00011695161199687929 0.999999772902834 0.2259039859928694
  children [
    LightSensor {
      translation 0.007 -0.07 0.013
      rotation 0 0 1 -1.5707953071795862
      children [
        Solid {
          children [
            Shape {
              appearance PBRAppearance {
                baseColor 1 1 0
              }
              geometry Box {
                size 0.002 0.01 0.01
              }
            }
          ]
        }
      ]
    }
    GPS {
      children [
        Solid {
          translation 0 0 0.01
          children [
            Shape {
              appearance PBRAppearance {
              }
              geometry Cylinder {
                height 0.01
                radius 0.0025
              }
            }
          ]
        }
      ]
      name "middleGPS"
    }
    GPS {
      translation 0 -0.07 0
      children [
        Solid {
          translation 0 0 0.01
          rotation 0 0 1 3.14159
          children [
            Shape {
              appearance PBRAppearance {
              }
              geometry Cylinder {
                height 0.01
                radius 0.0025
              }
            }
          ]
        }
      ]
      name "frontGPS"
    }
    Solid {
      translation 0 0 0.003
      children [
        Shape {
          appearance PBRAppearance {
          }
          geometry Box {
            size 0.08 0.15 0.003125
          }
        }
      ]
      name "solid(2)"
    }
    Solid {
      translation 0 0 0.006
      rotation 0 1 0 0
      children [
        Shape {
          appearance PBRAppearance {
            baseColor 0.666667 0 1
          }
          geometry Box {
            size 0.08 0.15 0.003125
          }
        }
      ]
      name "solid(3)"
    }
    BallJoint {
      jointParameters BallJointParameters {
        position -2.0655154222569414
        anchor 0 0.06 -0.02
      }
      jointParameters2 JointParameters {
        position -21.14903346362728
      }
      jointParameters3 JointParameters {
        position 5.66252467950093
        axis 0 1 0
      }
      endPoint Solid {
        translation 0 0.06 -0.02
        rotation -0.6148831533312771 0.7593113885435431 -0.21299042930953896 2.2331280570475
        children [
          DEF caster Shape {
            appearance PBRAppearance {
            }
            geometry Sphere {
              radius 0.01
            }
          }
        ]
        boundingObject USE caster
        physics Physics {
        }
      }
    }
    Solid {
      translation 0 0.06 -0.01
      children [
        Shape {
          appearance PBRAppearance {
            baseColor 0 0 0
          }
          geometry Cylinder {
            height 0.017
            radius 0.011
          }
        }
      ]
      name "solid(1)"
    }
    HingeJoint {
      jointParameters HingeJointParameters {
        position 2.740210974820109e-08
        anchor 0 -0.04 0
      }
      device [
        DEF wheel_left RotationalMotor {
          name "wheel_left"
          maxVelocity 30
        }
      ]
      endPoint DEF wheel_left Solid {
        translation 0.04296759999999994 -0.03998419999974723 -1.4646688262021372e-05
        rotation 0.5775878509908918 0.5773364172172278 -0.5771264469269264 4.189461511676189
        children [
          DEF wheel_left Shape {
            appearance PBRAppearance {
              baseColor 0.145098 0.145098 0.145098
              metalness 0
            }
            geometry Cylinder {
              height 0.005
              radius 0.03
            }
          }
        ]
        name "wheel_left"
        boundingObject USE wheel_left
        physics DEF Physics_wh Physics {
        }
      }
    }
    HingeJoint {
      jointParameters HingeJointParameters {
        position 0.008791816832634277
        anchor 0 -0.04 0
      }
      device [
        DEF wheel_right RotationalMotor {
          name "wheel_right"
          maxVelocity 30
        }
      ]
      endPoint DEF wheel_right Solid {
        translation -0.042031599999999975 -0.039920075042362904 -1.386176943598116e-05
        rotation 0.5758883126444175 0.5807193570791794 -0.5754282576247972 4.194530556268155
        children [
          DEF wheel_right Shape {
            appearance PBRAppearance {
              baseColor 0.145098 0.145098 0.145098
              metalness 0
            }
            geometry Cylinder {
              height 0.005
              radius 0.03
            }
          }
        ]
        name "wheel_right"
        boundingObject USE wheel_right
        physics DEF Physics_wh Physics {
        }
      }
    }
    DEF Body1 Shape {
      appearance PBRAppearance {
        baseColor 1 0.666667 1
      }
      geometry Box {
        size 0.08 0.15 0.003125
      }
    }
  ]
  name "robot(1)"
  boundingObject USE Body1
  physics Physics {
  }
  controller "pyController"
}
Robot {
  translation -0.0397203 -1.92331 0.03005
  rotation -0.0006637142462494745 -0.00011695161199687929 0.999999772902834 0.2259039859928694
  children [
    LightSensor {
      translation 0.007 -0.07 0.013
      rotation 0 0 1 -1.5707953071795862
      children [
        Solid {
          children [
            Shape {
              appearance PBRAppearance {
                baseColor 1 1 0
              }
              geometry Box {
                size 0.002 0.01 0.01
              }
            }
          ]
        }
      ]
    }
    GPS {
      children [
        Solid {
          translation 0 0 0.01
          children [
            Shape {
              appearance PBRAppearance {
              }
              geometry Cylinder {
                height 0.01
                radius 0.0025
              }
            }
          ]
        }
      ]
      name "middleGPS"
    }
    GPS {
      translation 0 -0.07 0
      children [
        Solid {
          translation 0 0 0.01
          rotation 0 0 1 3.14159
          children [
            Shape {
              appearance PBRAppearance {
              }
              geometry Cylinder {
                height 0.01
                radius 0.0025
              }
            }
          ]
        }
      ]
      name "frontGPS"
    }
    Solid {
      translation 0 0 0.003
      children [
        Shape {
          appearance PBRAppearance {
          }
          geometry Box {
            size 0.08 0.15 0.003125
          }
        }
      ]
      name "solid(2)"
    }
    Solid {
      translation 0 0 0.006
      rotation 0 1 0 0
      children [
        Shape {
          appearance PBRAppearance {
            baseColor 0.666667 0 1
          }
          geometry Box {
            size 0.08 0.15 0.003125
          }
        }
      ]
      name "solid(3)"
    }
    BallJoint {
      jointParameters BallJointParameters {
        position -2.0655154222569414
        anchor 0 0.06 -0.02
      }
      jointParameters2 JointParameters {
        position -21.14903346362728
      }
      jointParameters3 JointParameters {
        position 5.66252467950093
        axis 0 1 0
      }
      endPoint Solid {
        translation 0 0.06 -0.02
        rotation -0.6148831533312771 0.7593113885435431 -0.21299042930953896 2.2331280570475
        children [
          DEF caster Shape {
            appearance PBRAppearance {
            }
            geometry Sphere {
              radius 0.01
            }
          }
        ]
        boundingObject USE caster
        physics Physics {
        }
      }
    }
    Solid {
      translation 0 0.06 -0.01
      children [
        Shape {
          appearance PBRAppearance {
            baseColor 0 0 0
          }
          geometry Cylinder {
            height 0.017
            radius 0.011
          }
        }
      ]
      name "solid(1)"
    }
    HingeJoint {
      jointParameters HingeJointParameters {
        position 2.740210974820109e-08
        anchor 0 -0.04 0
      }
      device [
        DEF wheel_left RotationalMotor {
          name "wheel_left"
          maxVelocity 30
        }
      ]
      endPoint DEF wheel_left Solid {
        translation 0.04296759999999994 -0.03998419999974723 -1.4646688262021372e-05
        rotation 0.5775878509908918 0.5773364172172278 -0.5771264469269264 4.189461511676189
        children [
          DEF wheel_left Shape {
            appearance PBRAppearance {
              baseColor 0.145098 0.145098 0.145098
              metalness 0
            }
            geometry Cylinder {
              height 0.005
              radius 0.03
            }
          }
        ]
        name "wheel_left"
        boundingObject USE wheel_left
        physics DEF Physics_wh Physics {
        }
      }
    }
    HingeJoint {
      jointParameters HingeJointParameters {
        position 0.008791816832634277
        anchor 0 -0.04 0
      }
      device [
        DEF wheel_right RotationalMotor {
          name "wheel_right"
          maxVelocity 30
        }
      ]
      endPoint DEF wheel_right Solid {
        translation -0.042031599999999975 -0.039920075042362904 -1.386176943598116e-05
        rotation 0.5758883126444175 0.5807193570791794 -0.5754282576247972 4.194530556268155
        children [
          DEF wheel_right Shape {
            appearance PBRAppearance {
              baseColor 0.145098 0.145098 0.145098
              metalness 0
            }
            geometry Cylinder {
              height 0.005
              radius 0.03
            }
          }
        ]
        name "wheel_right"
        boundingObject USE wheel_right
        physics DEF Physics_wh Physics {
        }
      }
    }
    DEF Body1 Shape {
      appearance PBRAppearance {
        baseColor 1 0.666667 1
      }
      geometry Box {
        size 0.08 0.15 0.003125
      }
    }
  ]
  name "robot(2)"
  boundingObject USE Body1
  physics Physics {
  }
  controller "pyController"
}
Floor {
  translation -0.45 -2.78 0.01
  rotation 0 0 1 1.57079633
  name "floor(4)"
  size 0.04 2.5
  tileSize 1 1
  appearance Parquetry {
    type "chequered"
    colorOverride 0 0 0
  }
}
Floor {
  translation -1.7 -0.8 0.01
  name "floor(2)"
  size 0.04 4
  tileSize 1 1
  appearance Parquetry {
    type "chequered"
    colorOverride 0 0 0
  }
}
Floor {
  translation -0.6 -1.05 0
  size 3.5 5.8
  appearance Parquetry {
    type "light strip"
  }
}
Robot {
  translation -0.42 -1.94 0.05
  children [
    PointLight {
      attenuation 0 0 1
      color 0 0.333333 1
      intensity 0.1
    }
    Solid {
      children [
        Shape {
          appearance PBRAppearance {
            baseColor 0 0.666667 1
            transparency 0.1
          }
          geometry Box {
            size 0.1 0.1 0.1
          }
        }
      ]
    }
  ]
  name "target"
}
