#VRML_SIM R2022a utf8
WorldInfo {
  basicTimeStep 20
  optimalThreadCount 4
}
Viewpoint {
  fieldOfView 1.1
  orientation 0.3817143070340118 -0.6101117338842222 -0.6943038671808853 4.629699803926887
  position 0.020008657632441487 -0.5822413627939342 0.8994819039357081
  exposure 0.7999999999999999
}
TexturedBackground {
  texture "empty_office"
  skybox FALSE
  skyColor [
    0.2 0.2 0.2
  ]
}
Robot {
  translation 0.291139 -0.00289643 0.0400624
  rotation 0.0002694767081947588 1.0285413399530637e-05 -0.9999999636382565 1.5846374780430053
  children [
    InertialUnit {
      rotation 0 0 1 -1.5707953071795862
      children [
        Solid {
          translation 0 0 0.06
          children [
            Shape {
              appearance PBRAppearance {
              }
              geometry Cylinder {
                height 0.1
                radius 0.000625
              }
            }
          ]
        }
      ]
    }
    DistanceSensor {
      translation 5.19723e-15 -0.13 0.004
      rotation 0 0 1 -1.5707953071795862
      children [
        Solid {
          translation -0.1 0 0
          children [
            Shape {
              appearance PBRAppearance {
                baseColor 1 0 0
              }
              geometry Box {
                size 0.0025 0.01 0.0125
              }
            }
          ]
        }
      ]
      type "infra-red"
      numberOfRays 37
    }
    DistanceSensor {
      translation 1.23017e-07 -0.1 -0.00269998
      rotation 0.577349935856137 0.5773509358560258 -0.577349935856137 2.09439
      children [
        Solid {
          translation 0 0 -0.06
          children [
            Shape {
              appearance PBRAppearance {
                baseColor 1 0 0
              }
              geometry Box {
                size 0.0025 0.01 0.00675
              }
            }
          ]
        }
      ]
      name "ground_ds"
      type "infra-red"
    }
    LightSensor {
      translation 0.007 -0.07 0.013
      rotation 0 0 1 -1.5707953071795862
      children [
        Solid {
          translation -0.01 -0.02 0
          children [
            Shape {
              appearance PBRAppearance {
                baseColor 1 1 0
              }
              geometry Box {
                size 0.002 0.01 0.01
              }
            }
          ]
        }
      ]
    }
    GPS {
      children [
        Solid {
          translation 0 0 0.01
          children [
            Shape {
              appearance PBRAppearance {
              }
              geometry Cylinder {
                height 0.01
                radius 0.0025
              }
            }
          ]
        }
      ]
      name "middleGPS"
    }
    GPS {
      translation 0 -0.07 0
      children [
        Solid {
          translation 2.65359e-08 0.01 0.01
          rotation 0 0 1 3.14159
          children [
            Shape {
              appearance PBRAppearance {
              }
              geometry Cylinder {
                height 0.01
                radius 0.0025
              }
            }
          ]
        }
      ]
      name "frontGPS"
    }
    Solid {
      translation 0 0 0.003
      children [
        Shape {
          appearance PBRAppearance {
          }
          geometry Box {
            size 0.11 0.13 0.003125
          }
        }
      ]
      name "solid(2)"
    }
    Solid {
      translation 0 0 0.006
      rotation 0 1 0 0
      children [
        Shape {
          appearance PBRAppearance {
            baseColor 0.666667 0 1
          }
          geometry Box {
            size 0.11 0.13 0.003125
          }
        }
      ]
      name "solid(3)"
    }
    BallJoint {
      jointParameters BallJointParameters {
        position -43.11193187535873
        anchor 0 0.06 -0.02
      }
      jointParameters2 JointParameters {
        position -144.23317930803134
      }
      jointParameters3 JointParameters {
        position -360.4690652556564
        axis 0 1 0
      }
      endPoint Solid {
        translation 6.693537512954937e-07 0.059999947847937087 -0.019999509051121443
        rotation -0.8093464070487966 -0.5307162786590629 -0.25159217985358673 4.317263579852344
        children [
          DEF caster Shape {
            appearance PBRAppearance {
            }
            geometry Sphere {
              radius 0.01
            }
          }
        ]
        boundingObject USE caster
        physics Physics {
        }
      }
    }
    BallJoint {
      jointParameters BallJointParameters {
        position -41.01351771477373
        anchor 0 -0.06 -0.02
      }
      jointParameters2 JointParameters {
        position -144.76811684986995
      }
      jointParameters3 JointParameters {
        position -383.2551587140965
        axis 0 1 0
      }
    }
    Solid {
      translation 0 0.06 -0.01
      children [
        Shape {
          appearance PBRAppearance {
            baseColor 0 0 0
          }
          geometry Cylinder {
            height 0.017
            radius 0.011
          }
        }
      ]
      name "solid(1)"
    }
    HingeJoint {
      jointParameters HingeJointParameters {
        position 127.19608745541338
        anchor 0.058 7.41444e-06 5.47319e-05
      }
      device [
        DEF wheel_left RotationalMotor {
          name "wheel_left"
          maxVelocity 30
        }
      ]
      endPoint DEF wheel_left Solid {
        translation 0.058 5.8347e-05 -2.6015700000000104e-06
        rotation 0.036205167124076044 0.9986893767263212 -0.03617616186813426 4.711876638565324
        children [
          DEF wheel_left Shape {
            appearance PBRAppearance {
              baseColor 0.145098 0.145098 0.145098
              metalness 0
            }
            geometry Cylinder {
              height 0.005
              radius 0.03
            }
          }
        ]
        name "wheel_left"
        boundingObject USE wheel_left
        physics DEF Physics_wh Physics {
        }
      }
    }
    HingeJoint {
      jointParameters HingeJointParameters {
        position 55.988264093667986
        anchor -0.058 -3.68501e-05 5.42871e-05
      }
      device [
        DEF wheel_right RotationalMotor {
          name "wheel_right"
          maxVelocity 30
        }
      ]
      endPoint DEF wheel_right Solid {
        translation -0.058 6.150729999999963e-06 -3.6725799999999946e-05
        rotation -0.6587070619746317 -0.364558670249786 0.6581808128853776 2.441907632865235
        children [
          DEF wheel_right Shape {
            appearance PBRAppearance {
              baseColor 0.145098 0.145098 0.145098
              metalness 0
            }
            geometry Cylinder {
              height 0.005
              radius 0.03
            }
          }
        ]
        name "wheel_right"
        boundingObject USE wheel_right
        physics DEF Physics_wh Physics {
        }
      }
    }
    DEF Body1 Shape {
      appearance PBRAppearance {
        baseColor 1 0.666667 1
      }
      geometry Box {
        size 0.11 0.13 0.003125
      }
    }
  ]
  name "robot(1)"
  boundingObject USE Body1
  physics Physics {
  }
  controller "pyController"
  synchronization FALSE
}
Robot {
  translation 0.313661 0.17822 0.0400952
  rotation 0.0002694767081947588 1.0285413399530637e-05 -0.9999999636382565 1.5846374780430053
  children [
    InertialUnit {
      rotation 0 0 1 -1.5707953071795862
      children [
        Solid {
          translation 0 0 0.06
          children [
            Shape {
              appearance PBRAppearance {
              }
              geometry Cylinder {
                height 0.1
                radius 0.000625
              }
            }
          ]
        }
      ]
    }
    DistanceSensor {
      translation 5.19723e-15 -0.13 0.004
      rotation 0 0 1 -1.5707953071795862
      children [
        Solid {
          translation -0.1 0 0
          children [
            Shape {
              appearance PBRAppearance {
                baseColor 1 0 0
              }
              geometry Box {
                size 0.0025 0.01 0.0125
              }
            }
          ]
        }
      ]
      type "infra-red"
      numberOfRays 37
    }
    DistanceSensor {
      translation 1.23017e-07 -0.1 -0.00269998
      rotation 0.577349935856137 0.5773509358560258 -0.577349935856137 2.09439
      children [
        Solid {
          translation 0 0 -0.06
          children [
            Shape {
              appearance PBRAppearance {
                baseColor 1 0 0
              }
              geometry Box {
                size 0.0025 0.01 0.00675
              }
            }
          ]
        }
      ]
      name "ground_ds"
      type "infra-red"
    }
    LightSensor {
      translation 0.007 -0.07 0.013
      rotation 0 0 1 -1.5707953071795862
      children [
        Solid {
          translation -0.01 -0.02 0
          children [
            Shape {
              appearance PBRAppearance {
                baseColor 1 1 0
              }
              geometry Box {
                size 0.002 0.01 0.01
              }
            }
          ]
        }
      ]
    }
    GPS {
      children [
        Solid {
          translation 0 0 0.01
          children [
            Shape {
              appearance PBRAppearance {
              }
              geometry Cylinder {
                height 0.01
                radius 0.0025
              }
            }
          ]
        }
      ]
      name "middleGPS"
    }
    GPS {
      translation 0 -0.07 0
      children [
        Solid {
          translation 2.65359e-08 0.01 0.01
          rotation 0 0 1 3.14159
          children [
            Shape {
              appearance PBRAppearance {
              }
              geometry Cylinder {
                height 0.01
                radius 0.0025
              }
            }
          ]
        }
      ]
      name "frontGPS"
    }
    Solid {
      translation 0 0 0.003
      children [
        Shape {
          appearance PBRAppearance {
          }
          geometry Box {
            size 0.11 0.13 0.003125
          }
        }
      ]
      name "solid(2)"
    }
    Solid {
      translation 0 0 0.006
      rotation 0 1 0 0
      children [
        Shape {
          appearance PBRAppearance {
            baseColor 0.666667 0 1
          }
          geometry Box {
            size 0.11 0.13 0.003125
          }
        }
      ]
      name "solid(3)"
    }
    BallJoint {
      jointParameters BallJointParameters {
        position -43.11193187535873
        anchor 0 0.06 -0.02
      }
      jointParameters2 JointParameters {
        position -144.23317930803134
      }
      jointParameters3 JointParameters {
        position -360.4690652556564
        axis 0 1 0
      }
      endPoint Solid {
        translation 6.693537512954937e-07 0.059999947847937087 -0.019999509051121443
        rotation -0.8093464070487966 -0.5307162786590629 -0.25159217985358673 4.317263579852344
        children [
          DEF caster Shape {
            appearance PBRAppearance {
            }
            geometry Sphere {
              radius 0.01
            }
          }
        ]
        boundingObject USE caster
        physics Physics {
        }
      }
    }
    BallJoint {
      jointParameters BallJointParameters {
        position -41.01351771477373
        anchor 0 -0.06 -0.02
      }
      jointParameters2 JointParameters {
        position -144.76811684986995
      }
      jointParameters3 JointParameters {
        position -383.2551587140965
        axis 0 1 0
      }
    }
    Solid {
      translation 0 0.06 -0.01
      children [
        Shape {
          appearance PBRAppearance {
            baseColor 0 0 0
          }
          geometry Cylinder {
            height 0.017
            radius 0.011
          }
        }
      ]
      name "solid(1)"
    }
    HingeJoint {
      jointParameters HingeJointParameters {
        position 127.19608745541338
        anchor 0.058 7.41444e-06 5.47319e-05
      }
      device [
        DEF wheel_left RotationalMotor {
          name "wheel_left"
          maxVelocity 30
        }
      ]
      endPoint DEF wheel_left Solid {
        translation 0.058 5.8347e-05 -2.6015700000000104e-06
        rotation 0.036205167124076044 0.9986893767263212 -0.03617616186813426 4.711876638565324
        children [
          DEF wheel_left Shape {
            appearance PBRAppearance {
              baseColor 0.145098 0.145098 0.145098
              metalness 0
            }
            geometry Cylinder {
              height 0.005
              radius 0.03
            }
          }
        ]
        name "wheel_left"
        boundingObject USE wheel_left
        physics DEF Physics_wh Physics {
        }
      }
    }
    HingeJoint {
      jointParameters HingeJointParameters {
        position 55.988264093667986
        anchor -0.058 -3.68501e-05 5.42871e-05
      }
      device [
        DEF wheel_right RotationalMotor {
          name "wheel_right"
          maxVelocity 30
        }
      ]
      endPoint DEF wheel_right Solid {
        translation -0.058 6.150729999999963e-06 -3.6725799999999946e-05
        rotation -0.6587070619746317 -0.364558670249786 0.6581808128853776 2.441907632865235
        children [
          DEF wheel_right Shape {
            appearance PBRAppearance {
              baseColor 0.145098 0.145098 0.145098
              metalness 0
            }
            geometry Cylinder {
              height 0.005
              radius 0.03
            }
          }
        ]
        name "wheel_right"
        boundingObject USE wheel_right
        physics DEF Physics_wh Physics {
        }
      }
    }
    DEF Body1 Shape {
      appearance PBRAppearance {
        baseColor 1 0.666667 1
      }
      geometry Box {
        size 0.11 0.13 0.003125
      }
    }
  ]
  name "robot(2)"
  boundingObject USE Body1
  physics Physics {
  }
  controller "pyController"
  synchronization FALSE
}
Robot {
  translation -0.09 0.59 0.06
  children [
    PointLight {
      attenuation 0 0 1
      color 0 0.333333 1
      intensity 0.02
    }
    Solid {
      children [
        Shape {
          appearance PBRAppearance {
            baseColor 0 0.666667 1
            metalness 0
          }
          geometry Box {
            size 0.1 0.1 0.1
          }
        }
      ]
    }
  ]
  name "target"
}
Floor {
  translation 0.8 0.9 0
  name "floor(1)"
  size 2.4 2.4
  tileSize 0.2 0.2
  appearance Parquetry {
    type "light strip"
  }
}
Floor {
  translation 0.8 2 0.01
  name "floor(2)"
  size 2.4 0.2
  tileSize 0.2 0.2
  appearance NULL
}
Floor {
  translation 0.8 2.5 0.01
  name "floor(6)"
  size 2.4 0.2
  tileSize 0.2 0.2
  appearance Parquetry {
    colorOverride 0 0 0
  }
}
Floor {
  translation 0.1 0.4 2e-05
  name "floor(7)"
  size 0.6 0.2
  tileSize 0.2 0.2
  appearance Parquetry {
    colorOverride 0 0 0
  }
}
Floor {
  translation 0.9 0.5 2e-05
  rotation 0 0 1 1.5708
  name "floor(9)"
  size 1.2 0.2
  tileSize 0.2 0.2
  appearance Parquetry {
    colorOverride 0 0 0
  }
}
Floor {
  translation 0.1 1.2 2e-05
  name "floor(8)"
  size 0.6 0.2
  tileSize 0.2 0.2
  appearance Parquetry {
    colorOverride 0 0 0
  }
}
Floor {
  translation 1.5 1.4 2e-05
  name "floor(10)"
  size 0.6 0.2
  tileSize 0.2 0.2
  appearance Parquetry {
    colorOverride 0 0 0
  }
}
Floor {
  translation -0.3 0.9 0.01
  rotation 0 0 1 -1.5708
  name "floor(4)"
  size 2 0.2
  tileSize 0.2 0.2
  appearance NULL
}
Floor {
  translation 1.9 0.9 0.01
  rotation 0 0 1 -1.5708
  name "floor(5)"
  size 2 0.2
  tileSize 0.2 0.2
  appearance NULL
}
Floor {
  translation 0.8 -0.2 0.01
  name "floor(3)"
  size 2.4 0.2
  tileSize 0.2 0.2
  appearance NULL
}
