#VRML_SIM R2022a utf8
WorldInfo {
  basicTimeStep 20
}
Viewpoint {
  fieldOfView 1.1
  orientation -0.607553261645754 0.16310903902569457 0.777350934682477 2.761557934586135
  position 1.6170791769595536 0.05997528210924241 4.262198366996803
  exposure 0.7999999999999999
}
TexturedBackground {
  texture "empty_office"
  skybox FALSE
  skyColor [
    0.2 0.2 0.2
  ]
}
Robot {
  translation 0.69299 0.00126199 0.0401345
  rotation -0.00015023299813099776 4.8077299401885195e-05 0.9999999875593096 -1.506305307179586
  children [
    InertialUnit {
      rotation 0 0 1 -1.5707953071795862
      children [
        Solid {
          translation 0 0 0.06
          children [
            Shape {
              appearance PBRAppearance {
              }
              geometry Cylinder {
                height 0.1
                radius 0.000625
              }
            }
          ]
        }
      ]
    }
    DistanceSensor {
      translation 0.02 -0.07 0.004
      rotation 0 0 1 -1.5707953071795862
      children [
        Solid {
          children [
            Shape {
              appearance PBRAppearance {
                baseColor 1 0 0
              }
              geometry Box {
                size 0.0025 0.01 0.0125
              }
            }
          ]
        }
      ]
      type "infra-red"
    }
    DistanceSensor {
      translation 1.12124e-13 -0.07 -0.00270004
      rotation 0.577349935856137 0.5773509358560258 -0.577349935856137 2.09439
      children [
        Solid {
          children [
            Shape {
              appearance PBRAppearance {
                baseColor 1 0 0
              }
              geometry Box {
                size 0.0025 0.01 0.00675
              }
            }
          ]
        }
      ]
      name "ground_ds"
      type "infra-red"
    }
    LightSensor {
      translation 0.007 -0.07 0.013
      rotation 0 0 1 -1.5707953071795862
      children [
        Solid {
          translation 0 -0.02 0
          children [
            Shape {
              appearance PBRAppearance {
                baseColor 1 1 0
              }
              geometry Box {
                size 0.002 0.01 0.01
              }
            }
          ]
        }
      ]
    }
    GPS {
      children [
        Solid {
          translation 0 0 0.01
          children [
            Shape {
              appearance PBRAppearance {
              }
              geometry Cylinder {
                height 0.01
                radius 0.0025
              }
            }
          ]
        }
      ]
      name "middleGPS"
    }
    GPS {
      translation 0 -0.07 0
      children [
        Solid {
          translation 0 0 0.01
          rotation 0 0 1 3.14159
          children [
            Shape {
              appearance PBRAppearance {
              }
              geometry Cylinder {
                height 0.01
                radius 0.0025
              }
            }
          ]
        }
      ]
      name "frontGPS"
    }
    Solid {
      translation 0 0 0.003
      children [
        Shape {
          appearance PBRAppearance {
          }
          geometry Box {
            size 0.11 0.15 0.003125
          }
        }
      ]
      name "solid(2)"
    }
    Solid {
      translation 0 0 0.006
      rotation 0 1 0 0
      children [
        Shape {
          appearance PBRAppearance {
            baseColor 0.666667 0 1
          }
          geometry Box {
            size 0.11 0.15 0.003125
          }
        }
      ]
      name "solid(3)"
    }
    BallJoint {
      jointParameters BallJointParameters {
        position -62.45275292447171
        anchor 0 0.06 -0.02
      }
      jointParameters2 JointParameters {
        position -183.0077780781426
      }
      jointParameters3 JointParameters {
        position -347.00844401753324
        axis 0 1 0
      }
      endPoint Solid {
        translation -4.761347877387496e-07 0.060000147877886496 -0.02000007577128737
        rotation -0.7997287030128453 -0.3961396206215434 -0.4511179474940139 2.9070824880522457
        children [
          DEF caster Shape {
            appearance PBRAppearance {
            }
            geometry Sphere {
              radius 0.01
            }
          }
        ]
        boundingObject USE caster
        physics Physics {
        }
      }
    }
    Solid {
      translation 0 0.06 -0.01
      children [
        Shape {
          appearance PBRAppearance {
            baseColor 0 0 0
          }
          geometry Cylinder {
            height 0.017
            radius 0.011
          }
        }
      ]
      name "solid(1)"
    }
    HingeJoint {
      jointParameters HingeJointParameters {
        position 69.40070965496857
        anchor 0.058 -0.04 0
      }
      device [
        DEF wheel_left RotationalMotor {
          name "wheel_left"
          maxVelocity 30
        }
      ]
      endPoint DEF wheel_left Solid {
        translation 0.058 -0.0399959 -2.3570099999965233e-06
        rotation 0.5152913843673587 0.6851085094955616 -0.5148797135385517 4.343661145301338
        children [
          DEF wheel_left Shape {
            appearance PBRAppearance {
              baseColor 0.145098 0.145098 0.145098
              metalness 0
            }
            geometry Cylinder {
              height 0.005
              radius 0.03
            }
          }
        ]
        name "wheel_left"
        boundingObject USE wheel_left
        physics DEF Physics_wh Physics {
        }
      }
    }
    HingeJoint {
      jointParameters HingeJointParameters {
        position 1.4509276606581587
        anchor -0.058 -0.04 0
      }
      device [
        DEF wheel_right RotationalMotor {
          name "wheel_right"
          maxVelocity 30
        }
      ]
      endPoint DEF wheel_right Solid {
        translation -0.058 -0.0399536 -1.4008699999997208e-05
        rotation 0.059215745484079436 0.9964901443294527 -0.059168300136400176 4.709672098666368
        children [
          DEF wheel_right Shape {
            appearance PBRAppearance {
              baseColor 0.145098 0.145098 0.145098
              metalness 0
            }
            geometry Cylinder {
              height 0.005
              radius 0.03
            }
          }
        ]
        name "wheel_right"
        boundingObject USE wheel_right
        physics DEF Physics_wh Physics {
        }
      }
    }
    DEF Body1 Shape {
      appearance PBRAppearance {
        baseColor 1 0.666667 1
      }
      geometry Box {
        size 0.11 0.15 0.003125
      }
    }
  ]
  boundingObject USE Body1
  physics Physics {
  }
  controller "pyController"
}
Robot {
  translation -0.07 0.63 0.06
  children [
    PointLight {
      attenuation 0 0 1
      color 0 0.333333 1
      intensity 0.02
    }
    Solid {
      children [
        Shape {
          appearance PBRAppearance {
            baseColor 0 0.666667 1
            metalness 0
          }
          geometry Box {
            size 0.1 0.1 0.1
          }
        }
      ]
    }
  ]
  name "target"
}
Floor {
  translation 0.8 0.9 0
  name "floor(1)"
  size 2.4 2.4
  tileSize 0.2 0.2
  appearance Parquetry {
    type "light strip"
  }
}
Floor {
  translation 0.8 2 0.01
  name "floor(2)"
  size 2.4 0.2
  tileSize 0.2 0.2
  appearance NULL
}
Floor {
  translation 0.8 2.5 0.01
  name "floor(6)"
  size 2.4 0.2
  tileSize 0.2 0.2
  appearance Parquetry {
    colorOverride 0 0 0
  }
}
Floor {
  translation 0.1 0.4 2e-05
  name "floor(7)"
  size 0.6 0.2
  tileSize 0.2 0.2
  appearance Parquetry {
    colorOverride 0 0 0
  }
}
Floor {
  translation 0.9 0.5 2e-05
  rotation 0 0 1 1.5708
  name "floor(9)"
  size 1.2 0.2
  tileSize 0.2 0.2
  appearance Parquetry {
    colorOverride 0 0 0
  }
}
Floor {
  translation 0.1 1.2 2e-05
  name "floor(8)"
  size 0.6 0.2
  tileSize 0.2 0.2
  appearance Parquetry {
    colorOverride 0 0 0
  }
}
Floor {
  translation 1.5 1.4 2e-05
  name "floor(10)"
  size 0.6 0.2
  tileSize 0.2 0.2
  appearance Parquetry {
    colorOverride 0 0 0
  }
}
Floor {
  translation -0.3 0.9 0.01
  rotation 0 0 1 -1.5708
  name "floor(4)"
  size 2 0.2
  tileSize 0.2 0.2
  appearance NULL
}
Floor {
  translation 1.9 0.9 0.01
  rotation 0 0 1 -1.5708
  name "floor(5)"
  size 2 0.2
  tileSize 0.2 0.2
  appearance NULL
}
Floor {
  translation 0.8 -0.2 0.01
  name "floor(3)"
  size 2.4 0.2
  tileSize 0.2 0.2
  appearance NULL
}
