#VRML_SIM R2022a utf8
WorldInfo {
}
Viewpoint {
  fieldOfView 1.1
  orientation 0.47403401224966174 -0.011870706217912584 -0.8804265111662504 3.145256018948139
  position 3.3012011235952134 -0.07764939939606702 5.697851084847439
  exposure 0.7999999999999999
}
TexturedBackground {
  texture "empty_office"
  skybox FALSE
  skyColor [
    0.2 0.2 0.2
  ]
}
Wall {
  translation -2.25 1.35 0
  name "wall(4)"
}
Wall {
  translation -2.25 -0.45 0
  name "wall(5)"
}
Wall {
  translation -2.25 -2.985 0
  name "wall(6)"
  size 0.2 2.07 2.4
}
Wall {
  translation -0.5 -3.92 0
  name "wall(7)"
  size 3.3 0.2 2.4
}
Door {
  hidden translation_5 0.0010000008115729209 2.5458191110772077e-10 0
  hidden rotation_5 0 0 1 0
  translation -2.25 -1.45 0
  position -1.3037321711106966e-08
}
SolidBox {
  translation -2.146 0.455 0.03
  rotation 0 0 1 1.5708
  name "box(6)"
  size 2.8 0.01 0.07
  appearance PBRAppearance {
    baseColor 0.8 0.8 0.8
    roughness 0.5
    metalness 0
    textureTransform TextureTransform {
      scale 1 8
    }
  }
}
SolidBox {
  translation -2.145 -2.885 0.03
  rotation 0 0 1 1.5708
  name "box(7)"
  size 1.87 0.01 0.07
  appearance PBRAppearance {
    baseColor 0.8 0.8 0.8
    roughness 0.5
    metalness 0
    textureTransform TextureTransform {
      scale 1 8
    }
  }
}
SolidBox {
  translation -0.495 -3.815 0.03
  rotation 0 0 1 3.14159
  size 3.29 0.01 0.07
  appearance PBRAppearance {
    baseColor 0.8 0.8 0.8
    roughness 0.5
    metalness 0
    textureTransform TextureTransform {
      scale 1 8
    }
  }
}
Window {
  translation -2.25 0.45 0
  rotation 0 0 1 3.14159
  name "window(1)"
  bottomWallHeight 0.9
  windowHeight 1
  windowSillSize 0.01 0.05
}
Floor {
  translation 0.8 -0.8 0.01
  name "floor(1)"
  size 0.04 4
  tileSize 1 1
  appearance Parquetry {
    type "chequered"
    colorOverride 0 0 0
  }
}
Floor {
  translation -1.35 0 0.01
  rotation 0 0 1 1.57079633
  name "floor(5)"
  size 0.04 0.7
  tileSize 1 1
  appearance Parquetry {
    type "chequered"
    colorOverride 0 0 0
  }
}
Floor {
  translation -0.66 -2.078 0.01
  rotation 0 0 1 1.57079633
  name "floor(7)"
  size 0.04 0.7
  tileSize 1 1
  appearance Parquetry {
    type "chequered"
    colorOverride 0 0 0
  }
}
Floor {
  translation 0.45 -1.5 0.01
  rotation 0 0 1 1.57079633
  name "floor(9)"
  size 0.04 0.7
  tileSize 1 1
  appearance Parquetry {
    type "chequered"
    colorOverride 0 0 0
  }
}
Floor {
  translation -0.3 0.81 0.01
  name "floor(11)"
  size 0.04 0.7
  tileSize 1 1
  appearance Parquetry {
    type "chequered"
    colorOverride 0 0 0
  }
}
Floor {
  translation 0.03 0.45 0.01
  rotation 0 0 1 1.57079633
  name "floor(10)"
  size 0.04 0.7
  tileSize 0.5 1
  appearance Parquetry {
    type "chequered"
    colorOverride 0 0 0
  }
}
Floor {
  translation -1.025 -1.05 0.01
  name "floor(8)"
  size 0.04 2.1
  tileSize 1 1
  appearance Parquetry {
    type "light strip"
    colorOverride 0 0 0
  }
}
Floor {
  translation -0.4 -0.6 0.01
  name "floor(12)"
  size 0.04 1
  tileSize 1 1
  appearance Parquetry {
    type "chequered"
    colorOverride 0 0 0
  }
}
Floor {
  translation -0.1 -0.6 0.01
  rotation 0 0 1 1.5707996938995747
  name "floor(13)"
  size 0.04 0.6
  tileSize 1 1
  appearance Parquetry {
    type "chequered"
    colorOverride 0 0 0
  }
}
Floor {
  translation -0.45 1.175 0.01
  rotation 0 0 1 1.57079633
  name "floor(3)"
  size 0.04 2.5
  tileSize 1 1
  appearance Parquetry {
    type "chequered"
    colorOverride 0 0 0
  }
}
Robot {
  translation 0.0178891162473087 -2.039431219071449 0.039983908129106245
  rotation 0.0009551929172799766 -0.0011627837736800342 0.9999988677695523 0.27142326624590934
  children [
    InertialUnit {
      rotation 0 0 1 -1.5707953071795862
      children [
        Solid {
          translation 0 0 0.06
          children [
            Shape {
              appearance PBRAppearance {
              }
              geometry Cylinder {
                height 0.1
                radius 0.000625
              }
            }
          ]
        }
      ]
    }
    DistanceSensor {
      translation 0.02 -0.07 0.004
      rotation 0 0 1 -1.5707953071795862
      children [
        Solid {
          children [
            Shape {
              appearance PBRAppearance {
                baseColor 1 0 0
              }
              geometry Box {
                size 0.0025 0.01 0.0125
              }
            }
          ]
        }
      ]
      type "infra-red"
    }
    DistanceSensor {
      translation 1.12124e-13 -0.07 -0.00270004
      rotation 0.577349935856137 0.5773509358560258 -0.577349935856137 2.09439
      children [
        Solid {
          children [
            Shape {
              appearance PBRAppearance {
                baseColor 1 0 0
              }
              geometry Box {
                size 0.0025 0.01 0.00675
              }
            }
          ]
        }
      ]
      name "ground_ds"
      type "infra-red"
    }
    LightSensor {
      translation 0.007 -0.07 0.013
      rotation 0 0 1 -1.5707953071795862
      children [
        Solid {
          translation 0 -0.02 0
          children [
            Shape {
              appearance PBRAppearance {
                baseColor 1 1 0
              }
              geometry Box {
                size 0.002 0.01 0.01
              }
            }
          ]
        }
      ]
    }
    GPS {
      children [
        Solid {
          translation 0 0 0.01
          children [
            Shape {
              appearance PBRAppearance {
              }
              geometry Cylinder {
                height 0.01
                radius 0.0025
              }
            }
          ]
        }
      ]
      name "middleGPS"
    }
    GPS {
      translation 0 -0.07 0
      children [
        Solid {
          translation 0 0 0.01
          rotation 0 0 1 3.14159
          children [
            Shape {
              appearance PBRAppearance {
              }
              geometry Cylinder {
                height 0.01
                radius 0.0025
              }
            }
          ]
        }
      ]
      name "frontGPS"
    }
    Solid {
      translation 0 0 0.003
      children [
        Shape {
          appearance PBRAppearance {
          }
          geometry Box {
            size 0.11 0.15 0.003125
          }
        }
      ]
      name "solid(2)"
    }
    Solid {
      translation 0 0 0.006
      rotation 0 1 0 0
      children [
        Shape {
          appearance PBRAppearance {
            baseColor 0.666667 0 1
          }
          geometry Box {
            size 0.11 0.15 0.003125
          }
        }
      ]
      name "solid(3)"
    }
    BallJoint {
      jointParameters BallJointParameters {
        position -57.36287324626265
        anchor 0 0.06 -0.02
      }
      jointParameters2 JointParameters {
        position -176.85470667327127
      }
      jointParameters3 JointParameters {
        position -238.77547970855204
        axis 0 1 0
      }
      endPoint Solid {
        translation 4.3297232787953277e-07 0.0600002570968412 -0.019999972619880253
        rotation -0.7975096493263274 0.5995210754815898 0.06747473071303074 -2.879058603070047
        children [
          DEF caster Shape {
            appearance PBRAppearance {
            }
            geometry Sphere {
              radius 0.01
            }
          }
        ]
        boundingObject USE caster
        physics Physics {
        }
        linearVelocity 5.490760454225437e-08 -2.2679694174203586e-08 4.0771302018488405e-08
        angularVelocity 2.2685769624579867e-06 5.490171654449526e-06 -0.0004535930844681575
      }
    }
    Solid {
      translation 0 0.06 -0.01
      children [
        Shape {
          appearance PBRAppearance {
            baseColor 0 0 0
          }
          geometry Cylinder {
            height 0.017
            radius 0.011
          }
        }
      ]
      name "solid(1)"
    }
    HingeJoint {
      jointParameters HingeJointParameters {
        position 15.9353554137414
        anchor 0.057 -0.04 0
      }
      device [
        DEF wheel_left RotationalMotor {
          name "wheel_left"
          maxVelocity 30
        }
      ]
      endPoint DEF wheel_left Solid {
        translation 0.057 -0.04000396132139594 2.592139196231247e-06
        rotation 0.6161055866294557 -0.4913593221434953 -0.6156134523113178 2.2275374271656903
        children [
          DEF wheel_left Shape {
            appearance PBRAppearance {
              baseColor 0.145098 0.145098 0.145098
              metalness 0
            }
            geometry Cylinder {
              height 0.005
              radius 0.03
            }
          }
        ]
        name "wheel_left"
        boundingObject USE wheel_left
        physics DEF Physics_wh Physics {
        }
        linearVelocity -1.1288448536678323e-07 -2.915007342966758e-09 2.6973418954141412e-08
        angularVelocity -9.001683524791086e-07 2.03915349588624e-06 4.8822383104061285e-08
      }
    }
    HingeJoint {
      jointParameters HingeJointParameters {
        position -15.036021604697911
        anchor -0.057 -0.04 0
      }
      device [
        DEF wheel_right RotationalMotor {
          name "wheel_right"
          maxVelocity 30
        }
      ]
      endPoint DEF wheel_right Solid {
        translation -0.057 -0.04002314207948371 4.2532628322020876e-05
        rotation 0.6696573070358735 -0.32223329166784415 -0.669122407990024 2.5176708002649226
        children [
          DEF wheel_right Shape {
            appearance PBRAppearance {
              baseColor 0.145098 0.145098 0.145098
              metalness 0
            }
            geometry Cylinder {
              height 0.005
              radius 0.03
            }
          }
        ]
        name "wheel_right"
        boundingObject USE wheel_right
        physics DEF Physics_wh Physics {
        }
        linearVelocity 2.2476404054818824e-07 7.216918918904776e-08 6.193885925290044e-08
        angularVelocity -3.989828401509578e-07 2.398900543176853e-07 1.5369616329870899e-07
      }
    }
    DEF Body1 Shape {
      appearance PBRAppearance {
        baseColor 1 0.666667 1
      }
      geometry Box {
        size 0.11 0.15 0.003125
      }
    }
  ]
  boundingObject USE Body1
  physics Physics {
  }
  controller "pyController"
}
Floor {
  translation -0.45 -2.78 0.01
  rotation 0 0 1 1.57079633
  name "floor(4)"
  size 0.04 2.5
  tileSize 1 1
  appearance Parquetry {
    type "chequered"
    colorOverride 0 0 0
  }
}
Floor {
  translation -1.7 -0.8 0.01
  name "floor(2)"
  size 0.04 4
  tileSize 1 1
  appearance Parquetry {
    type "chequered"
    colorOverride 0 0 0
  }
}
Floor {
  translation -0.6 -1.05 0
  size 3.5 5.8
  appearance Parquetry {
    type "light strip"
  }
}
Robot {
  translation -0.51 -1.14 0.06
  children [
    PointLight {
      attenuation 0 0 1
      color 0 0.333333 1
      intensity 0.02
    }
    Solid {
      children [
        Shape {
          appearance PBRAppearance {
            baseColor 0 0.666667 1
            metalness 0
          }
          geometry Box {
            size 0.1 0.1 0.1
          }
        }
      ]
    }
  ]
  name "target"
}
