#VRML_SIM R2022a utf8
WorldInfo {
}
Viewpoint {
  fieldOfView 1.1
  orientation -0.41091597583550044 0.0038935840850263816 0.9116649059858185 3.1709658646602437
  position 1.0284338776884667 -0.3914838548380428 1.588826488074479
  exposure 0.7999999999999999
}
TexturedBackground {
  texture "empty_office"
  skybox FALSE
  skyColor [
    0.2 0.2 0.2
  ]
}
Wall {
  translation -2.25 1.35 0
  name "wall(4)"
}
Wall {
  translation -2.25 -0.45 0
  name "wall(5)"
}
Wall {
  translation -2.25 -2.985 0
  name "wall(6)"
  size 0.2 2.07 2.4
}
Wall {
  translation -0.5 -3.92 0
  name "wall(7)"
  size 3.3 0.2 2.4
}
Door {
  translation -2.25 -1.45 0
  position -5.106191098869428e-09
}
SolidBox {
  translation -2.146 0.455 0.03
  rotation 0 0 1 1.5708
  name "box(6)"
  size 2.8 0.01 0.07
  appearance PBRAppearance {
    baseColor 0.8 0.8 0.8
    roughness 0.5
    metalness 0
    textureTransform TextureTransform {
      scale 1 8
    }
  }
}
SolidBox {
  translation -2.145 -2.885 0.03
  rotation 0 0 1 1.5708
  name "box(7)"
  size 1.87 0.01 0.07
  appearance PBRAppearance {
    baseColor 0.8 0.8 0.8
    roughness 0.5
    metalness 0
    textureTransform TextureTransform {
      scale 1 8
    }
  }
}
SolidBox {
  translation -0.495 -3.815 0.03
  rotation 0 0 1 3.14159
  size 3.29 0.01 0.07
  appearance PBRAppearance {
    baseColor 0.8 0.8 0.8
    roughness 0.5
    metalness 0
    textureTransform TextureTransform {
      scale 1 8
    }
  }
}
Window {
  translation -2.25 0.45 0
  rotation 0 0 1 3.14159
  name "window(1)"
  bottomWallHeight 0.9
  windowHeight 1
  windowSillSize 0.01 0.05
}
CeilingLight {
  translation -0.93 -1.04 2.4
  pointLightColor 1 0.9764705882352941 0.9058823529411765
  pointLightIntensity 4
}
Floor {
  translation 0.8 -0.8 0.01
  name "floor(1)"
  size 0.04 4
  tileSize 1 1
  appearance Parquetry {
    type "chequered"
    colorOverride 0 0 0
  }
}
Floor {
  translation -1.35 0 0.01
  rotation 0 0 1 1.57079633
  name "floor(5)"
  size 0.04 0.7
  tileSize 1 1
  appearance Parquetry {
    type "chequered"
    colorOverride 0 0 0
  }
}
Floor {
  translation -0.66 -2.078 0.01
  rotation 0 0 1 1.57079633
  name "floor(7)"
  size 0.04 0.7
  tileSize 1 1
  appearance Parquetry {
    type "chequered"
    colorOverride 0 0 0
  }
}
Floor {
  translation 0.45 -1.5 0.01
  rotation 0 0 1 1.57079633
  name "floor(9)"
  size 0.04 0.7
  tileSize 1 1
  appearance Parquetry {
    type "chequered"
    colorOverride 0 0 0
  }
}
Floor {
  translation -0.3 0.81 0.01
  name "floor(11)"
  size 0.04 0.7
  tileSize 1 1
  appearance Parquetry {
    type "chequered"
    colorOverride 0 0 0
  }
}
Floor {
  translation 0.03 0.45 0.01
  rotation 0 0 1 1.57079633
  name "floor(10)"
  size 0.04 0.7
  tileSize 0.5 1
  appearance Parquetry {
    type "chequered"
    colorOverride 0 0 0
  }
}
Floor {
  translation -1.025 -1.05 0.01
  name "floor(8)"
  size 0.04 2.1
  tileSize 1 1
  appearance Parquetry {
    type "chequered"
    colorOverride 0 0 0
  }
}
Floor {
  translation -0.4 -0.6 0.01
  name "floor(12)"
  size 0.04 1
  tileSize 1 1
  appearance Parquetry {
    type "chequered"
    colorOverride 0 0 0
  }
}
Floor {
  translation -0.1 -0.6 0.01
  rotation 0 0 1 1.5707996938995747
  name "floor(13)"
  size 0.04 0.6
  tileSize 1 1
  appearance Parquetry {
    type "chequered"
    colorOverride 0 0 0
  }
}
Floor {
  translation -0.45 1.175 0.01
  rotation 0 0 1 1.57079633
  name "floor(3)"
  size 0.04 2.5
  tileSize 1 1
  appearance Parquetry {
    type "chequered"
    colorOverride 0 0 0
  }
}
Robot {
  translation -1.178004192220489e-05 -0.009486047143880653 0.040006567427944686
  rotation -7.704761974878778e-05 -7.813700480934495e-05 0.9999999939791364 1.570800006148867
  children [
    Compass {
      children [
        Solid {
          translation 0 -0.016 0.01
          children [
            Shape {
              appearance PBRAppearance {
              }
              geometry Cylinder {
                height 0.004
                radius 0.01
              }
            }
          ]
        }
      ]
    }
    Accelerometer {
      children [
        Solid {
          translation 0 -0.05 0.008
          children [
            Shape {
              appearance PBRAppearance {
              }
              geometry Box {
                size 0.02 0.02 0.0025
              }
            }
          ]
        }
      ]
    }
    GPS {
      children [
        Solid {
          translation 0 0 0.01
          children [
            Shape {
              appearance PBRAppearance {
              }
              geometry Cylinder {
                height 0.01
                radius 0.0025
              }
            }
          ]
        }
      ]
      name "middleGPS"
    }
    GPS {
      translation 0 -0.07 0
      children [
        Solid {
          translation 0 0 0.01
          rotation 0 0 1 3.14159
          children [
            Shape {
              appearance PBRAppearance {
              }
              geometry Cylinder {
                height 0.01
                radius 0.0025
              }
            }
          ]
        }
      ]
      name "frontGPS"
    }
    Solid {
      translation 0 0 0.003
      children [
        Shape {
          appearance PBRAppearance {
          }
          geometry Box {
            size 0.08 0.15 0.003125
          }
        }
      ]
      name "solid(2)"
    }
    Solid {
      translation 0 0 0.006
      children [
        Shape {
          appearance PBRAppearance {
            baseColor 0.666667 0 1
          }
          geometry Box {
            size 0.08 0.15 0.003125
          }
        }
      ]
      name "solid(3)"
    }
    BallJoint {
      jointParameters BallJointParameters {
        position -3.561672980001225e-09
        anchor 0 0.06 -0.02
      }
      jointParameters2 JointParameters {
        position 6.688041462102414e-08
      }
      jointParameters3 JointParameters {
        position -4.449749279455218e-06
        axis 0 1 0
      }
      endPoint Solid {
        translation 0 0.06 -0.02
        rotation 0.015028449476912472 -0.9998867461488097 -0.0008003638332720921 4.450236218728346e-06
        children [
          DEF caster Shape {
            appearance PBRAppearance {
            }
            geometry Sphere {
              radius 0.01
            }
          }
        ]
        boundingObject USE caster
        physics Physics {
        }
      }
    }
    Solid {
      translation 0 0.06 -0.01
      children [
        Shape {
          appearance PBRAppearance {
            baseColor 0 0 0
          }
          geometry Cylinder {
            height 0.017
            radius 0.011
          }
        }
      ]
      name "solid(1)"
    }
    HingeJoint {
      jointParameters HingeJointParameters {
        position 1.0194773332243325e-08
        anchor 0 -0.04 0
      }
      device [
        DEF wheel_left RotationalMotor {
          name "wheel_left"
        }
      ]
      endPoint DEF wheel_left Solid {
        translation 0.042967600000000016 -0.03998419999999926 -1.4646688533896998e-05
        rotation 0.5775878543036479 0.5773364105941207 -0.5771264502370386 4.189461501737441
        children [
          DEF wheel_left Shape {
            appearance PBRAppearance {
              baseColor 0.145098 0.145098 0.145098
              metalness 0
            }
            geometry Cylinder {
              height 0.005
              radius 0.03
            }
          }
        ]
        name "wheel_left"
        boundingObject USE wheel_left
        physics DEF Physics_wh Physics {
        }
      }
    }
    HingeJoint {
      jointParameters HingeJointParameters {
        position -9.87319126782544e-09
        anchor 0 -0.04 0
      }
      device [
        DEF wheel_right RotationalMotor {
          name "wheel_right"
        }
      ]
      endPoint DEF wheel_right Solid {
        translation -0.04203159999999999 -0.039920199999996145 -1.4563911032815018e-05
        rotation 0.5775883689596771 0.5773353898227673 -0.5771269563109084 4.189459961782076
        children [
          DEF wheel_right Shape {
            appearance PBRAppearance {
              baseColor 0.145098 0.145098 0.145098
              metalness 0
            }
            geometry Cylinder {
              height 0.005
              radius 0.03
            }
          }
        ]
        name "wheel_right"
        boundingObject USE wheel_right
        physics DEF Physics_wh Physics {
        }
      }
    }
    DEF Body1 Shape {
      appearance PBRAppearance {
        baseColor 1 0.666667 1
      }
      geometry Box {
        size 0.08 0.15 0.003125
      }
    }
  ]
  boundingObject USE Body1
  physics Physics {
  }
  controller "controller"
}
Robot {
  translation -0.589994 -0.00948861 0.049879
  rotation -7.773839974917054e-05 2.0246199934673942e-05 0.9999999967734163 -2.617985307179586
  children [
    Compass {
      children [
        Solid {
          translation 0 -0.016 0.01
          children [
            Shape {
              appearance PBRAppearance {
              }
              geometry Cylinder {
                height 0.004
                radius 0.01
              }
            }
          ]
        }
      ]
    }
    Accelerometer {
      children [
        Solid {
          translation 0 -0.05 0.008
          children [
            Shape {
              appearance PBRAppearance {
              }
              geometry Box {
                size 0.02 0.02 0.0025
              }
            }
          ]
        }
      ]
    }
    GPS {
      children [
        Solid {
          translation 0 0 0.01
          children [
            Shape {
              appearance PBRAppearance {
              }
              geometry Cylinder {
                height 0.01
                radius 0.0025
              }
            }
          ]
        }
      ]
      name "middleGPS"
    }
    GPS {
      translation 0 -0.07 0
      children [
        Solid {
          translation 0 0 0.01
          rotation 0 0 1 3.14159
          children [
            Shape {
              appearance PBRAppearance {
              }
              geometry Cylinder {
                height 0.01
                radius 0.0025
              }
            }
          ]
        }
      ]
      name "frontGPS"
    }
    Solid {
      translation 0 0 0.003
      children [
        Shape {
          appearance PBRAppearance {
          }
          geometry Box {
            size 0.08 0.15 0.003125
          }
        }
      ]
      name "solid(2)"
    }
    Solid {
      translation 0 0 0.006
      children [
        Shape {
          appearance PBRAppearance {
            baseColor 0.666667 0 1
          }
          geometry Box {
            size 0.08 0.15 0.003125
          }
        }
      ]
      name "solid(3)"
    }
    BallJoint {
      jointParameters BallJointParameters {
        position -3.561672980001225e-09
        anchor 0 0.06 -0.02
      }
      jointParameters2 JointParameters {
        position 6.688041462102414e-08
      }
      jointParameters3 JointParameters {
        position -4.449749279455218e-06
        axis 0 1 0
      }
      endPoint Solid {
        translation 0 0.06 -0.02
        rotation 0.015028449476912472 -0.9998867461488097 -0.0008003638332720921 4.450236218728346e-06
        children [
          DEF caster Shape {
            appearance PBRAppearance {
            }
            geometry Sphere {
              radius 0.01
            }
          }
        ]
        boundingObject USE caster
        physics Physics {
        }
      }
    }
    Solid {
      translation 0 0.06 -0.01
      children [
        Shape {
          appearance PBRAppearance {
            baseColor 0 0 0
          }
          geometry Cylinder {
            height 0.017
            radius 0.011
          }
        }
      ]
      name "solid(1)"
    }
    HingeJoint {
      jointParameters HingeJointParameters {
        position 1.0194773332243325e-08
        anchor 0 -0.04 0
      }
      device [
        DEF wheel_left RotationalMotor {
          name "wheel_left"
        }
      ]
      endPoint DEF wheel_left Solid {
        translation 0.042967600000000016 -0.03998419999999926 -1.4646688533896998e-05
        rotation 0.5775878543036479 0.5773364105941207 -0.5771264502370386 4.189461501737441
        children [
          DEF wheel_left Shape {
            appearance PBRAppearance {
              baseColor 0.145098 0.145098 0.145098
              metalness 0
            }
            geometry Cylinder {
              height 0.005
              radius 0.03
            }
          }
        ]
        name "wheel_left"
        boundingObject USE wheel_left
        physics DEF Physics_wh Physics {
        }
      }
    }
    HingeJoint {
      jointParameters HingeJointParameters {
        position -9.87319126782544e-09
        anchor 0 -0.04 0
      }
      device [
        DEF wheel_right RotationalMotor {
          name "wheel_right"
        }
      ]
      endPoint DEF wheel_right Solid {
        translation -0.04203159999999999 -0.039920199999996145 -1.4563911032815018e-05
        rotation 0.5775883689596771 0.5773353898227673 -0.5771269563109084 4.189459961782076
        children [
          DEF wheel_right Shape {
            appearance PBRAppearance {
              baseColor 0.145098 0.145098 0.145098
              metalness 0
            }
            geometry Cylinder {
              height 0.005
              radius 0.03
            }
          }
        ]
        name "wheel_right"
        boundingObject USE wheel_right
        physics DEF Physics_wh Physics {
        }
      }
    }
    DEF Body1 Shape {
      appearance PBRAppearance {
        baseColor 1 0.666667 1
      }
      geometry Box {
        size 0.08 0.15 0.003125
      }
    }
  ]
  name "robot(1)"
  boundingObject USE Body1
  physics Physics {
  }
  controller "controller"
}
Robot {
  translation 0.0550225 -0.953445 0.039973
  rotation 7.853629905427481e-05 -0.00013384999838819353 -0.9999999879581137 1.04719
  children [
    Compass {
      children [
        Solid {
          translation 0 -0.016 0.01
          children [
            Shape {
              appearance PBRAppearance {
              }
              geometry Cylinder {
                height 0.004
                radius 0.01
              }
            }
          ]
        }
      ]
    }
    Accelerometer {
      children [
        Solid {
          translation 0 -0.05 0.008
          children [
            Shape {
              appearance PBRAppearance {
              }
              geometry Box {
                size 0.02 0.02 0.0025
              }
            }
          ]
        }
      ]
    }
    GPS {
      children [
        Solid {
          translation 0 0 0.01
          children [
            Shape {
              appearance PBRAppearance {
              }
              geometry Cylinder {
                height 0.01
                radius 0.0025
              }
            }
          ]
        }
      ]
      name "middleGPS"
    }
    GPS {
      translation 0 -0.07 0
      children [
        Solid {
          translation 0 0 0.01
          rotation 0 0 1 3.14159
          children [
            Shape {
              appearance PBRAppearance {
              }
              geometry Cylinder {
                height 0.01
                radius 0.0025
              }
            }
          ]
        }
      ]
      name "frontGPS"
    }
    Solid {
      translation 0 0 0.003
      children [
        Shape {
          appearance PBRAppearance {
          }
          geometry Box {
            size 0.08 0.15 0.003125
          }
        }
      ]
      name "solid(2)"
    }
    Solid {
      translation 0 0 0.006
      children [
        Shape {
          appearance PBRAppearance {
            baseColor 0.666667 0 1
          }
          geometry Box {
            size 0.08 0.15 0.003125
          }
        }
      ]
      name "solid(3)"
    }
    BallJoint {
      jointParameters BallJointParameters {
        position -3.561672980001225e-09
        anchor 0 0.06 -0.02
      }
      jointParameters2 JointParameters {
        position 6.688041462102414e-08
      }
      jointParameters3 JointParameters {
        position -4.449749279455218e-06
        axis 0 1 0
      }
      endPoint Solid {
        translation 0 0.06 -0.02
        rotation 0.015028449476912472 -0.9998867461488097 -0.0008003638332720921 4.450236218728346e-06
        children [
          DEF caster Shape {
            appearance PBRAppearance {
            }
            geometry Sphere {
              radius 0.01
            }
          }
        ]
        boundingObject USE caster
        physics Physics {
        }
      }
    }
    Solid {
      translation 0 0.06 -0.01
      children [
        Shape {
          appearance PBRAppearance {
            baseColor 0 0 0
          }
          geometry Cylinder {
            height 0.017
            radius 0.011
          }
        }
      ]
      name "solid(1)"
    }
    HingeJoint {
      jointParameters HingeJointParameters {
        position 1.0194773332243325e-08
        anchor 0 -0.04 0
      }
      device [
        DEF wheel_left RotationalMotor {
          name "wheel_left"
        }
      ]
      endPoint DEF wheel_left Solid {
        translation 0.042967600000000016 -0.03998419999999926 -1.4646688533896998e-05
        rotation 0.5775878543036479 0.5773364105941207 -0.5771264502370386 4.189461501737441
        children [
          DEF wheel_left Shape {
            appearance PBRAppearance {
              baseColor 0.145098 0.145098 0.145098
              metalness 0
            }
            geometry Cylinder {
              height 0.005
              radius 0.03
            }
          }
        ]
        name "wheel_left"
        boundingObject USE wheel_left
        physics DEF Physics_wh Physics {
        }
      }
    }
    HingeJoint {
      jointParameters HingeJointParameters {
        position -9.87319126782544e-09
        anchor 0 -0.04 0
      }
      device [
        DEF wheel_right RotationalMotor {
          name "wheel_right"
        }
      ]
      endPoint DEF wheel_right Solid {
        translation -0.04203159999999999 -0.039920199999996145 -1.4563911032815018e-05
        rotation 0.5775883689596771 0.5773353898227673 -0.5771269563109084 4.189459961782076
        children [
          DEF wheel_right Shape {
            appearance PBRAppearance {
              baseColor 0.145098 0.145098 0.145098
              metalness 0
            }
            geometry Cylinder {
              height 0.005
              radius 0.03
            }
          }
        ]
        name "wheel_right"
        boundingObject USE wheel_right
        physics DEF Physics_wh Physics {
        }
      }
    }
    DEF Body1 Shape {
      appearance PBRAppearance {
        baseColor 1 0.666667 1
      }
      geometry Box {
        size 0.08 0.15 0.003125
      }
    }
  ]
  name "robot(2)"
  boundingObject USE Body1
  physics Physics {
  }
  controller "controller"
}
Floor {
  translation -0.45 -2.78 0.01
  rotation 0 0 1 1.57079633
  name "floor(4)"
  size 0.04 2.5
  tileSize 1 1
  appearance Parquetry {
    type "chequered"
    colorOverride 0 0 0
  }
}
Floor {
  translation -1.7 -0.8 0.01
  name "floor(2)"
  size 0.04 4
  tileSize 1 1
  appearance Parquetry {
    type "chequered"
    colorOverride 0 0 0
  }
}
CardboardBox {
  translation -0.26 -0.46 0.07
  rotation 1 0 0 4.692820414042842e-06
  size 0.1 0.1 0.1
}
Floor {
  translation -0.6 -1.05 0
  size 3.5 5.8
  appearance Parquetry {
    type "light strip"
  }
}
