#VRML_SIM R2022a utf8
WorldInfo {
}
Viewpoint {
  fieldOfView 1.1
  orientation 0.3085690545099693 0.6942653061503565 -0.6502159820204172 1.1339239631294429
  position -2.2450564948296883 1.1771980581725838 2.5046571475638832
  exposure 0.7999999999999999
}
TexturedBackground {
  texture "empty_office"
  skybox FALSE
  skyColor [
    0.2 0.2 0.2
  ]
}
Robot {
  translation 0 0 0.0400175
  rotation 0.0005682018489465946 -0.002102699091703375 0.9999976278987808 0.16321838505584121
  children [
    InertialUnit {
      rotation 0 0 1 -1.5707953071795862
      children [
        Solid {
          translation 0 0 0.06
          children [
            Shape {
              appearance PBRAppearance {
              }
              geometry Cylinder {
                height 0.1
                radius 0.000625
              }
            }
          ]
        }
      ]
    }
    DistanceSensor {
      translation 0.02 -0.07 0.004
      rotation 0 0 1 -1.5707953071795862
      children [
        Solid {
          children [
            Shape {
              appearance PBRAppearance {
                baseColor 1 0 0
              }
              geometry Box {
                size 0.0025 0.01 0.0125
              }
            }
          ]
        }
      ]
      type "infra-red"
    }
    DistanceSensor {
      translation 1.12124e-13 -0.07 -0.00270004
      rotation 0.577349935856137 0.5773509358560258 -0.577349935856137 2.09439
      children [
        Solid {
          children [
            Shape {
              appearance PBRAppearance {
                baseColor 1 0 0
              }
              geometry Box {
                size 0.0025 0.01 0.00675
              }
            }
          ]
        }
      ]
      name "ground_ds"
      type "infra-red"
    }
    LightSensor {
      translation 0.007 -0.07 0.013
      rotation 0 0 1 -1.5707953071795862
      children [
        Solid {
          translation 0 -0.02 0
          children [
            Shape {
              appearance PBRAppearance {
                baseColor 1 1 0
              }
              geometry Box {
                size 0.002 0.01 0.01
              }
            }
          ]
        }
      ]
    }
    GPS {
      children [
        Solid {
          translation 0 0 0.01
          children [
            Shape {
              appearance PBRAppearance {
              }
              geometry Cylinder {
                height 0.01
                radius 0.0025
              }
            }
          ]
        }
      ]
      name "middleGPS"
    }
    GPS {
      translation 0 -0.07 0
      children [
        Solid {
          translation 0 0 0.01
          rotation 0 0 1 3.14159
          children [
            Shape {
              appearance PBRAppearance {
              }
              geometry Cylinder {
                height 0.01
                radius 0.0025
              }
            }
          ]
        }
      ]
      name "frontGPS"
    }
    Solid {
      translation 0 0 0.003
      children [
        Shape {
          appearance PBRAppearance {
          }
          geometry Box {
            size 0.11 0.15 0.003125
          }
        }
      ]
      name "solid(2)"
    }
    Solid {
      translation 0 0 0.006
      rotation 0 1 0 0
      children [
        Shape {
          appearance PBRAppearance {
            baseColor 0.666667 0 1
          }
          geometry Box {
            size 0.11 0.15 0.003125
          }
        }
      ]
      name "solid(3)"
    }
    BallJoint {
      jointParameters BallJointParameters {
        position -58.952263509217225
        anchor 0 0.06 -0.02
      }
      jointParameters2 JointParameters {
        position -175.93954386933706
      }
      jointParameters3 JointParameters {
        position -330.18324998914346
        axis 0 1 0
      }
      endPoint Solid {
        translation 1.6914501244926544e-07 0.05999978991777514 -0.020000426109043484
        rotation 0.5096190474839262 0.24665385635200143 0.824287754117615 1.2493139881435917
        children [
          DEF caster Shape {
            appearance PBRAppearance {
            }
            geometry Sphere {
              radius 0.01
            }
          }
        ]
        boundingObject USE caster
        physics Physics {
        }
      }
    }
    Solid {
      translation 0 0.06 -0.01
      children [
        Shape {
          appearance PBRAppearance {
            baseColor 0 0 0
          }
          geometry Cylinder {
            height 0.017
            radius 0.011
          }
        }
      ]
      name "solid(1)"
    }
    HingeJoint {
      jointParameters HingeJointParameters {
        position 15.936312453227746
        anchor 0.057 -0.04 0
      }
      device [
        DEF wheel_left RotationalMotor {
          name "wheel_left"
          maxVelocity 30
        }
      ]
      endPoint DEF wheel_left Solid {
        translation 0.057 -0.040003963800360996 2.5883468687105705e-06
        rotation 0.6162515026730331 -0.4909935124943675 -0.6157592517710733 2.228127134375602
        children [
          DEF wheel_left Shape {
            appearance PBRAppearance {
              baseColor 0.145098 0.145098 0.145098
              metalness 0
            }
            geometry Cylinder {
              height 0.005
              radius 0.03
            }
          }
        ]
        name "wheel_left"
        boundingObject USE wheel_left
        physics DEF Physics_wh Physics {
        }
      }
    }
    HingeJoint {
      jointParameters HingeJointParameters {
        position -15.036021600965643
        anchor -0.057 -0.04 0
      }
      device [
        DEF wheel_right RotationalMotor {
          name "wheel_right"
          maxVelocity 30
        }
      ]
      endPoint DEF wheel_right Solid {
        translation -0.057 -0.04002314207964245 4.253262823565168e-05
        rotation 0.6696573073678079 -0.3222332902893096 -0.6691224083216933 2.517670802764263
        children [
          DEF wheel_right Shape {
            appearance PBRAppearance {
              baseColor 0.145098 0.145098 0.145098
              metalness 0
            }
            geometry Cylinder {
              height 0.005
              radius 0.03
            }
          }
        ]
        name "wheel_right"
        boundingObject USE wheel_right
        physics DEF Physics_wh Physics {
        }
      }
    }
    DEF Body1 Shape {
      appearance PBRAppearance {
        baseColor 1 0.666667 1
      }
      geometry Box {
        size 0.11 0.15 0.003125
      }
    }
  ]
  boundingObject USE Body1
  physics Physics {
  }
  controller "pyController"
}
Robot {
  translation -1.33 -0.62 0.06
  children [
    PointLight {
      attenuation 0 0 1
      color 0 0.333333 1
      intensity 0.02
    }
    Solid {
      children [
        Shape {
          appearance PBRAppearance {
            baseColor 0 0.666667 1
            metalness 0
          }
          geometry Box {
            size 0.1 0.1 0.1
          }
        }
      ]
    }
  ]
  name "target"
}
Floor {
  translation -0.9 -0.9 0
  name "floor(1)"
  size 2.4 2.4
  tileSize 0.2 0.2
}
Floor {
  translation -0.9 0.2 0.01
  name "floor(2)"
  size 2.4 0.2
  tileSize 0.2 0.2
  appearance NULL
}
Floor {
  translation -0.9 0.5 0.01
  name "floor(6)"
  size 2.4 0.2
  tileSize 0.2 0.2
  appearance Parquetry {
    colorOverride 0 0 0
  }
}
Floor {
  translation -0.2 -0.4 0.01
  name "floor(7)"
  size 0.6 0.2
  tileSize 0.2 0.2
  appearance Parquetry {
    colorOverride 0 0 0
  }
}
Floor {
  translation -1 -0.5 0.01
  rotation 0 0 1 1.5708
  name "floor(9)"
  size 1.2 0.2
  tileSize 0.2 0.2
  appearance Parquetry {
    colorOverride 0 0 0
  }
}
Floor {
  translation -0.2 -1.2 0.01
  name "floor(8)"
  size 0.6 0.2
  tileSize 0.2 0.2
  appearance Parquetry {
    colorOverride 0 0 0
  }
}
Floor {
  translation -1.6 -1.4 0.01
  name "floor(10)"
  size 0.6 0.2
  tileSize 0.2 0.2
  appearance Parquetry {
    colorOverride 0 0 0
  }
}
Floor {
  translation -2 -0.9 0.01
  rotation 0 0 1 -1.5708
  name "floor(4)"
  size 2 0.2
  tileSize 0.2 0.2
  appearance NULL
}
Floor {
  translation 0.2 -0.9 0.01
  rotation 0 0 1 -1.5708
  name "floor(5)"
  size 2 0.2
  tileSize 0.2 0.2
  appearance NULL
}
Floor {
  translation -0.9 -2 0.01
  name "floor(3)"
  size 2.4 0.2
  tileSize 0.2 0.2
  appearance NULL
}
