#VRML_SIM R2022a utf8
WorldInfo {
  basicTimeStep 20
  optimalThreadCount 4
}
Viewpoint {
  fieldOfView 1.1
  orientation 0.3428926264886562 -0.3293276287331103 -0.8797544882822353 4.62028475876173
  position 0.897418946882983 -1.9836060275486798 2.553351115100015
  exposure 0.7999999999999999
}
TexturedBackground {
  texture "empty_office"
  skybox FALSE
  skyColor [
    0.2 0.2 0.2
  ]
}
Robot {
  translation 0.8961264145913296 0.20918937728023565 0.040016202543411115
  rotation -0.00021892175059897229 -0.00013963311301296445 0.9999999662879299 3.1100000411635618
  children [
    InertialUnit {
      rotation 0 0 1 -1.5707953071795862
      children [
        Solid {
          translation 0 0 0.06
          children [
            Shape {
              appearance PBRAppearance {
              }
              geometry Cylinder {
                height 0.1
                radius 0.000625
              }
            }
          ]
        }
      ]
    }
    DistanceSensor {
      translation 5.19723e-15 -0.13 0.004
      rotation 0 0 1 -1.5707953071795862
      children [
        Solid {
          translation -0.1 0 0
          children [
            Shape {
              appearance PBRAppearance {
                baseColor 1 0 0
              }
              geometry Box {
                size 0.0025 0.01 0.0125
              }
            }
          ]
        }
      ]
      type "infra-red"
      numberOfRays 37
    }
    DistanceSensor {
      translation 1.23017e-07 -0.1 -0.00269998
      rotation 0.577349935856137 0.5773509358560258 -0.577349935856137 2.09439
      children [
        Solid {
          translation 0 0 -0.06
          children [
            Shape {
              appearance PBRAppearance {
                baseColor 1 0 0
              }
              geometry Box {
                size 0.0025 0.01 0.00675
              }
            }
          ]
        }
      ]
      name "ground_ds"
      type "infra-red"
    }
    LightSensor {
      translation 0.007 -0.07 0.013
      rotation 0 0 1 -1.5707953071795862
      children [
        Solid {
          translation -0.01 -0.02 0
          children [
            Shape {
              appearance PBRAppearance {
                baseColor 1 1 0
              }
              geometry Box {
                size 0.002 0.01 0.01
              }
            }
          ]
        }
      ]
    }
    GPS {
      children [
        Solid {
          translation 0 0 0.01
          children [
            Shape {
              appearance PBRAppearance {
              }
              geometry Cylinder {
                height 0.01
                radius 0.0025
              }
            }
          ]
        }
      ]
      name "middleGPS"
    }
    GPS {
      translation 0 -0.07 0
      children [
        Solid {
          translation 2.65359e-08 0.01 0.01
          rotation 0 0 1 3.14159
          children [
            Shape {
              appearance PBRAppearance {
              }
              geometry Cylinder {
                height 0.01
                radius 0.0025
              }
            }
          ]
        }
      ]
      name "frontGPS"
    }
    Solid {
      translation 0 0 0.003
      children [
        Shape {
          appearance PBRAppearance {
          }
          geometry Box {
            size 0.11 0.13 0.003125
          }
        }
      ]
      name "solid(2)"
    }
    Solid {
      translation 0 0 0.006
      rotation 0 1 0 0
      children [
        Shape {
          appearance PBRAppearance {
            baseColor 1 0 0
          }
          geometry Box {
            size 0.11 0.13 0.003125
          }
        }
      ]
      name "solid(3)"
    }
    BallJoint {
      jointParameters BallJointParameters {
        position -9561.876011191434
        anchor 0 0.06 -0.02
      }
      jointParameters2 JointParameters {
        position -102.2596814332094
      }
      jointParameters3 JointParameters {
        position -5552.728071852432
        axis 0 1 0
      }
      endPoint Solid {
        translation -7.737744910838302e-07 0.05999911581757149 -0.019999874161553598
        rotation 0.32683532824192235 -0.8787833528306339 -0.3477333561807732 1.7423117038045888
        children [
          DEF caster Shape {
            appearance PBRAppearance {
            }
            geometry Sphere {
              radius 0.01
            }
          }
        ]
        name "solid(5)"
        boundingObject USE caster
        physics Physics {
        }
      }
    }
    Solid {
      translation 0 0.06 -0.01
      children [
        Shape {
          appearance PBRAppearance {
            baseColor 0 0 0
          }
          geometry Cylinder {
            height 0.017
            radius 0.011
          }
        }
      ]
      name "solid(1)"
    }
    HingeJoint {
      jointParameters HingeJointParameters {
        position 209.0223629514718
        anchor 0.058 7.41444e-06 5.47319e-05
      }
      device [
        DEF wheel_left RotationalMotor {
          name "wheel_left"
          maxVelocity 30
        }
      ]
      endPoint DEF wheel_left Solid {
        translation 0.058000008659390874 6.574372118046986e-05 5.1686273642895825e-06
        rotation -0.032839551966755476 0.9989218409990807 0.03281340277432636 4.71210938510207
        children [
          DEF wheel_left Shape {
            appearance PBRAppearance {
              baseColor 0.145098 0.145098 0.145098
              metalness 0
            }
            geometry Cylinder {
              height 0.005
              radius 0.03
            }
          }
        ]
        name "wheel_left"
        boundingObject USE wheel_left
        physics DEF Physics_wh Physics {
        }
      }
    }
    HingeJoint {
      jointParameters HingeJointParameters {
        position 181.07651456119487
        anchor -0.058 -3.68501e-05 5.42871e-05
      }
      device [
        DEF wheel_right RotationalMotor {
          name "wheel_right"
          maxVelocity 30
        }
      ]
      endPoint DEF wheel_right Solid {
        translation -0.05800000876483282 -5.082204521915154e-05 -4.5218163147958725e-05
        rotation -0.6991331027678495 -0.1523366228759746 0.6985745901082737 2.8390060672561837
        children [
          DEF wheel_right Shape {
            appearance PBRAppearance {
              baseColor 0.145098 0.145098 0.145098
              metalness 0
            }
            geometry Cylinder {
              height 0.005
              radius 0.03
            }
          }
        ]
        name "wheel_right"
        boundingObject USE wheel_right
        physics DEF Physics_wh Physics {
        }
      }
    }
    DEF Body1 Shape {
      appearance PBRAppearance {
        baseColor 1 0.666667 1
      }
      geometry Box {
        size 0.11 0.13 0.003125
      }
    }
  ]
  name "robot(2)"
  boundingObject USE Body1
  physics Physics {
  }
  controller "pyController"
  synchronization FALSE
}
Robot {
  translation 0.4933307629348163 1.785812261294304 0.039953033224829924
  rotation 0.0011098387285927611 -0.0004201378034226855 0.9999992958708634 1.1907500567942182
  children [
    InertialUnit {
      rotation 0 0 1 -1.5707953071795862
      children [
        Solid {
          translation 0 0 0.06
          children [
            Shape {
              appearance PBRAppearance {
              }
              geometry Cylinder {
                height 0.1
                radius 0.000625
              }
            }
          ]
        }
      ]
    }
    DistanceSensor {
      translation 5.19723e-15 -0.13 0.004
      rotation 0 0 1 -1.5707953071795862
      children [
        Solid {
          translation -0.1 0 0
          children [
            Shape {
              appearance PBRAppearance {
                baseColor 1 0 0
              }
              geometry Box {
                size 0.0025 0.01 0.0125
              }
            }
          ]
        }
      ]
      type "infra-red"
      numberOfRays 37
    }
    DistanceSensor {
      translation 1.23017e-07 -0.1 -0.00269998
      rotation 0.577349935856137 0.5773509358560258 -0.577349935856137 2.09439
      children [
        Solid {
          translation 0 0 -0.06
          children [
            Shape {
              appearance PBRAppearance {
                baseColor 1 0 0
              }
              geometry Box {
                size 0.0025 0.01 0.00675
              }
            }
          ]
        }
      ]
      name "ground_ds"
      type "infra-red"
    }
    LightSensor {
      translation 0.007 -0.07 0.013
      rotation 0 0 1 -1.5707953071795862
      children [
        Solid {
          translation -0.01 -0.02 0
          children [
            Shape {
              appearance PBRAppearance {
                baseColor 1 1 0
              }
              geometry Box {
                size 0.002 0.01 0.01
              }
            }
          ]
        }
      ]
    }
    GPS {
      children [
        Solid {
          translation 0 0 0.01
          children [
            Shape {
              appearance PBRAppearance {
              }
              geometry Cylinder {
                height 0.01
                radius 0.0025
              }
            }
          ]
        }
      ]
      name "middleGPS"
    }
    GPS {
      translation 0 -0.07 0
      children [
        Solid {
          translation 2.65359e-08 0.01 0.01
          rotation 0 0 1 3.14159
          children [
            Shape {
              appearance PBRAppearance {
              }
              geometry Cylinder {
                height 0.01
                radius 0.0025
              }
            }
          ]
        }
      ]
      name "frontGPS"
    }
    Solid {
      translation 0 0 0.003
      children [
        Shape {
          appearance PBRAppearance {
          }
          geometry Box {
            size 0.11 0.13 0.003125
          }
        }
      ]
      name "solid(2)"
    }
    Solid {
      translation 0 0 0.006
      rotation 0 1 0 0
      children [
        Shape {
          appearance PBRAppearance {
            baseColor 0.666667 0 1
          }
          geometry Box {
            size 0.11 0.13 0.003125
          }
        }
      ]
      name "solid(3)"
    }
    BallJoint {
      jointParameters BallJointParameters {
        position 3935.278463984491
        anchor 0 0.06 -0.02
      }
      jointParameters2 JointParameters {
        position 448.8122615288059
      }
      jointParameters3 JointParameters {
        position 3196.552203363903
        axis 0 1 0
      }
      endPoint Solid {
        translation -7.162383789438356e-07 0.06000092893062076 -0.019999857895500198
        rotation 0.3548678594146793 -0.029577893763913357 -0.9344484739967924 3.5666154619394734
        children [
          DEF caster Shape {
            appearance PBRAppearance {
            }
            geometry Sphere {
              radius 0.01
            }
          }
        ]
        name "solid(5)"
        boundingObject USE caster
        physics Physics {
        }
      }
    }
    Solid {
      translation 0 0.06 -0.01
      children [
        Shape {
          appearance PBRAppearance {
            baseColor 0 0 0
          }
          geometry Cylinder {
            height 0.017
            radius 0.011
          }
        }
      ]
      name "solid(1)"
    }
    HingeJoint {
      jointParameters HingeJointParameters {
        position 270.7730827308618
        anchor 0.058 7.41444e-06 5.47319e-05
      }
      device [
        DEF wheel_left RotationalMotor {
          name "wheel_left"
          maxVelocity 30
        }
      ]
      endPoint DEF wheel_left Solid {
        translation 0.058000008659390874 -8.8907955374471e-06 -2.0054210551760795e-05
        rotation 0.4375361185946758 0.7857671890547436 -0.4371865385966417 4.4743730408834175
        children [
          DEF wheel_left Shape {
            appearance PBRAppearance {
              baseColor 0.145098 0.145098 0.145098
              metalness 0
            }
            geometry Cylinder {
              height 0.005
              radius 0.03
            }
          }
        ]
        name "wheel_left"
        boundingObject USE wheel_left
        physics DEF Physics_wh Physics {
        }
      }
    }
    HingeJoint {
      jointParameters HingeJointParameters {
        position 210.51506751656115
        anchor -0.058 -3.68501e-05 5.42871e-05
      }
      device [
        DEF wheel_right RotationalMotor {
          name "wheel_right"
          maxVelocity 30
        }
      ]
      endPoint DEF wheel_right Solid {
        translation -0.05800000876483282 -0.00012271821664703203 0.00010647118944154624
        rotation 0.5820026207373066 -0.5684072142446235 -0.5815377788670081 2.1071747215625143
        children [
          DEF wheel_right Shape {
            appearance PBRAppearance {
              baseColor 0.145098 0.145098 0.145098
              metalness 0
            }
            geometry Cylinder {
              height 0.005
              radius 0.03
            }
          }
        ]
        name "wheel_right"
        boundingObject USE wheel_right
        physics DEF Physics_wh Physics {
        }
      }
    }
    DEF Body1 Shape {
      appearance PBRAppearance {
        baseColor 1 0.666667 1
      }
      geometry Box {
        size 0.11 0.13 0.003125
      }
    }
  ]
  name "robot(3)"
  boundingObject USE Body1
  physics Physics {
  }
  controller "pyController"
  synchronization FALSE
}
Robot {
  translation -0.10964627477259489 1.2034730532678957 0.03998903734346627
  rotation 0.007501420236800165 -0.00861829553098993 0.9999347247078538 0.021019912518820724
  children [
    InertialUnit {
      rotation 0 0 1 -1.5707953071795862
      children [
        Solid {
          translation 0 0 0.06
          children [
            Shape {
              appearance PBRAppearance {
              }
              geometry Cylinder {
                height 0.1
                radius 0.000625
              }
            }
          ]
        }
      ]
    }
    DistanceSensor {
      translation 5.19723e-15 -0.13 0.004
      rotation 0 0 1 -1.5707953071795862
      children [
        Solid {
          translation -0.1 0 0
          children [
            Shape {
              appearance PBRAppearance {
                baseColor 1 0 0
              }
              geometry Box {
                size 0.0025 0.01 0.0125
              }
            }
          ]
        }
      ]
      type "infra-red"
      numberOfRays 37
    }
    DistanceSensor {
      translation 1.23017e-07 -0.1 -0.00269998
      rotation 0.577349935856137 0.5773509358560258 -0.577349935856137 2.09439
      children [
        Solid {
          translation 0 0 -0.06
          children [
            Shape {
              appearance PBRAppearance {
                baseColor 1 0 0
              }
              geometry Box {
                size 0.0025 0.01 0.00675
              }
            }
          ]
        }
      ]
      name "ground_ds"
      type "infra-red"
    }
    LightSensor {
      translation 0.007 -0.07 0.013
      rotation 0 0 1 -1.5707953071795862
      children [
        Solid {
          translation -0.01 -0.02 0
          children [
            Shape {
              appearance PBRAppearance {
                baseColor 1 1 0
              }
              geometry Box {
                size 0.002 0.01 0.01
              }
            }
          ]
        }
      ]
    }
    GPS {
      children [
        Solid {
          translation 0 0 0.01
          children [
            Shape {
              appearance PBRAppearance {
              }
              geometry Cylinder {
                height 0.01
                radius 0.0025
              }
            }
          ]
        }
      ]
      name "middleGPS"
    }
    GPS {
      translation 0 -0.07 0
      children [
        Solid {
          translation 2.65359e-08 0.01 0.01
          rotation 0 0 1 3.14159
          children [
            Shape {
              appearance PBRAppearance {
              }
              geometry Cylinder {
                height 0.01
                radius 0.0025
              }
            }
          ]
        }
      ]
      name "frontGPS"
    }
    Solid {
      translation 0 0 0.003
      children [
        Shape {
          appearance PBRAppearance {
          }
          geometry Box {
            size 0.11 0.13 0.003125
          }
        }
      ]
      name "solid(2)"
    }
    Solid {
      translation 0 0 0.006
      rotation 0 1 0 0
      children [
        Shape {
          appearance PBRAppearance {
            baseColor 0.666667 0 1
          }
          geometry Box {
            size 0.11 0.13 0.003125
          }
        }
      ]
      name "solid(3)"
    }
    BallJoint {
      jointParameters BallJointParameters {
        position -4521.166390229172
        anchor 0 0.06 -0.02
      }
      jointParameters2 JointParameters {
        position 1887.934446630622
      }
      jointParameters3 JointParameters {
        position 1495.888698849531
        axis 0 1 0
      }
      endPoint Solid {
        translation 6.22522501956748e-07 0.05999938784291154 -0.019999203491454568
        rotation -0.5718431389977428 0.4919303822410523 -0.65650584415478 2.77513972035277
        children [
          DEF caster Shape {
            appearance PBRAppearance {
            }
            geometry Sphere {
              radius 0.01
            }
          }
        ]
        name "solid(5)"
        boundingObject USE caster
        physics Physics {
        }
      }
    }
    Solid {
      translation 0 0.06 -0.01
      children [
        Shape {
          appearance PBRAppearance {
            baseColor 0 0 0
          }
          geometry Cylinder {
            height 0.017
            radius 0.011
          }
        }
      ]
      name "solid(1)"
    }
    HingeJoint {
      jointParameters HingeJointParameters {
        position 252.8459374632149
        anchor 0.058 7.41444e-06 5.47319e-05
      }
      device [
        DEF wheel_left RotationalMotor {
          name "wheel_left"
          maxVelocity 30
        }
      ]
      endPoint DEF wheel_left Solid {
        translation 0.058000008659390874 5.7176697519597694e-05 -3.427714544330761e-06
        rotation -0.04649445471264748 -0.9978376578626706 0.046457230138198365 1.572161871061236
        children [
          DEF wheel_left Shape {
            appearance PBRAppearance {
              baseColor 0.145098 0.145098 0.145098
              metalness 0
            }
            geometry Cylinder {
              height 0.005
              radius 0.03
            }
          }
        ]
        name "wheel_left"
        boundingObject USE wheel_left
        physics DEF Physics_wh Physics {
        }
      }
    }
    HingeJoint {
      jointParameters HingeJointParameters {
        position 188.69746691480026
        anchor -0.058 -3.68501e-05 5.42871e-05
      }
      device [
        DEF wheel_right RotationalMotor {
          name "wheel_right"
          maxVelocity 30
        }
      ]
      endPoint DEF wheel_right Solid {
        translation -0.05800000876483282 5.673918214687624e-05 1.7714447449437243e-05
        rotation 0.5359880844093781 0.6526043565869505 -0.5355598259157397 4.298731924331465
        children [
          DEF wheel_right Shape {
            appearance PBRAppearance {
              baseColor 0.145098 0.145098 0.145098
              metalness 0
            }
            geometry Cylinder {
              height 0.005
              radius 0.03
            }
          }
        ]
        name "wheel_right"
        boundingObject USE wheel_right
        physics DEF Physics_wh Physics {
        }
      }
    }
    DEF Body1 Shape {
      appearance PBRAppearance {
        baseColor 1 0.666667 1
      }
      geometry Box {
        size 0.11 0.13 0.003125
      }
    }
  ]
  name "robot(4)"
  boundingObject USE Body1
  physics Physics {
  }
  controller "pyController"
  synchronization FALSE
}
Robot {
  translation 1.50398 1.00981 0.0400785
  rotation 0.004074783231230415 -0.0011062927612054251 -0.9999910860892435 0.493654729464778
  children [
    InertialUnit {
      rotation 0 0 1 -1.5707953071795862
      children [
        Solid {
          translation 0 0 0.06
          children [
            Shape {
              appearance PBRAppearance {
              }
              geometry Cylinder {
                height 0.1
                radius 0.000625
              }
            }
          ]
        }
      ]
    }
    DistanceSensor {
      translation 5.19723e-15 -0.13 0.004
      rotation 0 0 1 -1.5707953071795862
      children [
        Solid {
          translation -0.1 0 0
          children [
            Shape {
              appearance PBRAppearance {
                baseColor 1 0 0
              }
              geometry Box {
                size 0.0025 0.01 0.0125
              }
            }
          ]
        }
      ]
      type "infra-red"
      numberOfRays 37
    }
    DistanceSensor {
      translation 1.23017e-07 -0.1 -0.00269998
      rotation 0.577349935856137 0.5773509358560258 -0.577349935856137 2.09439
      children [
        Solid {
          translation 0 0 -0.06
          children [
            Shape {
              appearance PBRAppearance {
                baseColor 1 0 0
              }
              geometry Box {
                size 0.0025 0.01 0.00675
              }
            }
          ]
        }
      ]
      name "ground_ds"
      type "infra-red"
    }
    LightSensor {
      translation 0.007 -0.07 0.013
      rotation 0 0 1 -1.5707953071795862
      children [
        Solid {
          translation -0.01 -0.02 0
          children [
            Shape {
              appearance PBRAppearance {
                baseColor 1 1 0
              }
              geometry Box {
                size 0.002 0.01 0.01
              }
            }
          ]
        }
      ]
    }
    GPS {
      children [
        Solid {
          translation 0 0 0.01
          children [
            Shape {
              appearance PBRAppearance {
              }
              geometry Cylinder {
                height 0.01
                radius 0.0025
              }
            }
          ]
        }
      ]
      name "middleGPS"
    }
    GPS {
      translation 0 -0.07 0
      children [
        Solid {
          translation 2.65359e-08 0.01 0.01
          rotation 0 0 1 3.14159
          children [
            Shape {
              appearance PBRAppearance {
              }
              geometry Cylinder {
                height 0.01
                radius 0.0025
              }
            }
          ]
        }
      ]
      name "frontGPS"
    }
    Solid {
      translation 0 0 0.003
      children [
        Shape {
          appearance PBRAppearance {
          }
          geometry Box {
            size 0.11 0.13 0.003125
          }
        }
      ]
      name "solid(2)"
    }
    Solid {
      translation 0 0 0.006
      rotation 0 1 0 0
      children [
        Shape {
          appearance PBRAppearance {
            baseColor 0.666667 0 1
          }
          geometry Box {
            size 0.11 0.13 0.003125
          }
        }
      ]
      name "solid(3)"
    }
    BallJoint {
      jointParameters BallJointParameters {
        position -2835.918042298493
        anchor 0 0.06 -0.02
      }
      jointParameters2 JointParameters {
        position -712.5403104262676
      }
      jointParameters3 JointParameters {
        position 8269.147742969668
        axis 0 1 0
      }
      endPoint Solid {
        translation 2.0441866189946716e-07 0.060000846380152136 -0.01999920097828642
        rotation -0.7344142412503404 -0.24455625590808605 -0.6331097534747872 2.4123568241957374
        children [
          DEF caster Shape {
            appearance PBRAppearance {
            }
            geometry Sphere {
              radius 0.01
            }
          }
        ]
        name "solid(5)"
        boundingObject USE caster
        physics Physics {
        }
      }
    }
    Solid {
      translation 0 0.06 -0.01
      children [
        Shape {
          appearance PBRAppearance {
            baseColor 0 0 0
          }
          geometry Cylinder {
            height 0.017
            radius 0.011
          }
        }
      ]
      name "solid(1)"
    }
    HingeJoint {
      jointParameters HingeJointParameters {
        position 424.3607380041338
        anchor 0.058 7.41444e-06 5.47319e-05
      }
      device [
        DEF wheel_left RotationalMotor {
          name "wheel_left"
          maxVelocity 30
        }
      ]
      endPoint DEF wheel_left Solid {
        translation 0.058000008659390874 4.840000213478876e-05 0.00011937713751899462
        rotation -0.6132387373760269 0.4984746980127569 0.6127489097685505 4.067084276867037
        children [
          DEF wheel_left Shape {
            appearance PBRAppearance {
              baseColor 0.145098 0.145098 0.145098
              metalness 0
            }
            geometry Cylinder {
              height 0.005
              radius 0.03
            }
          }
        ]
        name "wheel_left"
        boundingObject USE wheel_left
        physics DEF Physics_wh Physics {
        }
      }
    }
    HingeJoint {
      jointParameters HingeJointParameters {
        position 372.04508536524924
        anchor -0.058 -3.68501e-05 5.42871e-05
      }
      device [
        DEF wheel_right RotationalMotor {
          name "wheel_right"
          maxVelocity 30
        }
      ]
      endPoint DEF wheel_right Solid {
        translation -0.05800000876483282 3.579435649198629e-05 0.0001237082465501344
        rotation -0.11855268102893826 -0.9858564818751757 0.11845783623531252 1.5842412771244838
        children [
          DEF wheel_right Shape {
            appearance PBRAppearance {
              baseColor 0.145098 0.145098 0.145098
              metalness 0
            }
            geometry Cylinder {
              height 0.005
              radius 0.03
            }
          }
        ]
        name "wheel_right"
        boundingObject USE wheel_right
        physics DEF Physics_wh Physics {
        }
      }
    }
    DEF Body1 Shape {
      appearance PBRAppearance {
        baseColor 1 0.666667 1
      }
      geometry Box {
        size 0.11 0.13 0.003125
      }
    }
  ]
  name "robot(5)"
  boundingObject USE Body1
  physics Physics {
  }
  controller "pyController"
  synchronization FALSE
}
Robot {
  translation -0.5 -0.23 0.06
  children [
    PointLight {
      attenuation 0 0 1
      color 0 0.333333 1
      intensity 0.02
    }
    Solid {
      children [
        Shape {
          appearance PBRAppearance {
            baseColor 0 0.666667 1
            metalness 0
          }
          geometry Box {
            size 0.1 0.1 0.1
          }
        }
      ]
    }
  ]
  name "target"
}
Floor {
  translation 1 1.1 0
  name "floor(1)"
  size 2.8 2.8
  tileSize 0.2 0.2
  appearance Parquetry {
    type "light strip"
  }
}
Floor {
  translation 1 2.4 0.01
  name "floor(2)"
  size 2.8 0.2
  tileSize 0.2 0.2
  appearance NULL
}
Floor {
  translation 1 2.7 0.01
  name "floor(6)"
  size 2.4 0.2
  tileSize 0.2 0.2
  appearance Parquetry {
    colorOverride 0 0 0
  }
}
Floor {
  translation 0.1 0.6 2e-05
  name "floor(7)"
  size 0.6 0.2
  tileSize 0.2 0.2
  appearance Parquetry {
    colorOverride 0 0 0
  }
}
Floor {
  translation 1.3 0.8 2e-05
  rotation 0 0 1 -1.5708
  name "floor(9)"
  size 1 0.2
  tileSize 0.2 0.2
  appearance Parquetry {
    colorOverride 0 0 0
  }
}
Floor {
  translation 0.3 1 2e-05
  rotation 0 0 1 -1.5708
  name "floor(8)"
  size 0.6 0.2
  tileSize 0.2 0.2
  appearance Parquetry {
    colorOverride 0 0 0
  }
}
Floor {
  translation 1.5 1.4 2e-05
  name "floor(10)"
  size 0.6 0.2
  tileSize 0.2 0.2
  appearance Parquetry {
    colorOverride 0 0 0
  }
}
Floor {
  translation -0.3 1.1 0.01
  rotation 0 0 1 -1.5708
  name "floor(4)"
  size 2.4 0.2
  tileSize 0.2 0.2
  appearance NULL
}
Floor {
  translation 2.3 1.1 0.01
  rotation 0 0 1 -1.5708
  name "floor(5)"
  size 2.4 0.2
  tileSize 0.2 0.2
  appearance NULL
}
Floor {
  translation 1 -0.2 0.01
  name "floor(3)"
  size 2.8 0.2
  tileSize 0.2 0.2
  appearance NULL
}
CeilingLight {
  translation 0.46 1.67 2.4
}
